[2025-04-07T11:27:56.334+0000] {local_task_job_runner.py:123} INFO - ::group::Pre task execution logs
[2025-04-07T11:27:56.350+0000] {taskinstance.py:2614} INFO - Dependencies all met for dep_context=non-requeueable deps ti=<TaskInstance: meta_ads_elt_pipeline.airbyte_sync.trigger_connection_sync manual__2025-04-07T11:27:54.573381+00:00 [queued]>
[2025-04-07T11:27:56.357+0000] {taskinstance.py:2614} INFO - Dependencies all met for dep_context=requeueable deps ti=<TaskInstance: meta_ads_elt_pipeline.airbyte_sync.trigger_connection_sync manual__2025-04-07T11:27:54.573381+00:00 [queued]>
[2025-04-07T11:27:56.358+0000] {taskinstance.py:2867} INFO - Starting attempt 1 of 3
[2025-04-07T11:27:56.369+0000] {taskinstance.py:2890} INFO - Executing <Task(HttpOperator): airbyte_sync.trigger_connection_sync> on 2025-04-07 11:27:54.573381+00:00
[2025-04-07T11:27:56.382+0000] {warnings.py:112} WARNING - /home/***/.local/lib/python3.12/site-packages/***/task/task_runner/standard_task_runner.py:70: DeprecationWarning: This process (pid=3171) is multi-threaded, use of fork() may lead to deadlocks in the child.
  pid = os.fork()

[2025-04-07T11:27:56.384+0000] {standard_task_runner.py:72} INFO - Started process 3173 to run task
[2025-04-07T11:27:56.384+0000] {standard_task_runner.py:104} INFO - Running: ['***', 'tasks', 'run', 'meta_ads_elt_pipeline', 'airbyte_sync.trigger_connection_sync', 'manual__2025-04-07T11:27:54.573381+00:00', '--job-id', '109', '--raw', '--subdir', 'DAGS_FOLDER/meta_ads_dag.py', '--cfg-path', '/tmp/tmp_3x1wiga']
[2025-04-07T11:27:56.384+0000] {standard_task_runner.py:105} INFO - Job 109: Subtask airbyte_sync.trigger_connection_sync
[2025-04-07T11:27:56.425+0000] {task_command.py:467} INFO - Running <TaskInstance: meta_ads_elt_pipeline.airbyte_sync.trigger_connection_sync manual__2025-04-07T11:27:54.573381+00:00 [running]> on host ffa99f2ae5fe
[2025-04-07T11:27:56.495+0000] {taskinstance.py:3134} INFO - Exporting env vars: AIRFLOW_CTX_DAG_OWNER='admin' AIRFLOW_CTX_DAG_ID='meta_ads_elt_pipeline' AIRFLOW_CTX_TASK_ID='airbyte_sync.trigger_connection_sync' AIRFLOW_CTX_EXECUTION_DATE='2025-04-07T11:27:54.573381+00:00' AIRFLOW_CTX_TRY_NUMBER='1' AIRFLOW_CTX_DAG_RUN_ID='manual__2025-04-07T11:27:54.573381+00:00'
[2025-04-07T11:27:56.496+0000] {logging_mixin.py:190} INFO - Task instance is in running state
[2025-04-07T11:27:56.496+0000] {logging_mixin.py:190} INFO -  Previous state of the Task instance: queued
[2025-04-07T11:27:56.497+0000] {logging_mixin.py:190} INFO - Current task name:airbyte_sync.trigger_connection_sync state:running start_date:2025-04-07 11:27:56.351287+00:00
[2025-04-07T11:27:56.497+0000] {logging_mixin.py:190} INFO - Dag name:meta_ads_elt_pipeline and current dag run status:running
[2025-04-07T11:27:56.497+0000] {taskinstance.py:732} INFO - ::endgroup::
[2025-04-07T11:27:56.497+0000] {http.py:180} INFO - Calling HTTP method
[2025-04-07T11:27:56.504+0000] {base.py:84} INFO - Retrieving connection 'airbyte'
[2025-04-07T11:27:56.510+0000] {base.py:84} INFO - Retrieving connection 'airbyte'
[2025-04-07T11:27:56.534+0000] {http.py:278} ERROR - HTTP error: Conflict
[2025-04-07T11:27:56.534+0000] {http.py:279} ERROR - {"message":"A sync is already running for: 29c579af-667a-4bca-a9ab-12f750e68c02","exceptionClassName":"io.airbyte.commons.server.errors.ValueConflictKnownException","exceptionStack":[],"rootCauseExceptionStack":[]}
[2025-04-07T11:27:56.545+0000] {taskinstance.py:3313} ERROR - Task failed with exception
Traceback (most recent call last):
  File "/home/airflow/.local/lib/python3.12/site-packages/airflow/providers/http/hooks/http.py", line 276, in check_response
    response.raise_for_status()
  File "/home/airflow/.local/lib/python3.12/site-packages/requests/models.py", line 1024, in raise_for_status
    raise HTTPError(http_error_msg, response=self)
requests.exceptions.HTTPError: 409 Client Error: Conflict for url: http://192.168.1.130:8000/api/v1/connections/sync

During handling of the above exception, another exception occurred:

Traceback (most recent call last):
  File "/home/airflow/.local/lib/python3.12/site-packages/airflow/models/taskinstance.py", line 768, in _execute_task
    result = _execute_callable(context=context, **execute_callable_kwargs)
             ^^^^^^^^^^^^^^^^^^^^^^^^^^^^^^^^^^^^^^^^^^^^^^^^^^^^^^^^^^^^^
  File "/home/airflow/.local/lib/python3.12/site-packages/airflow/models/taskinstance.py", line 734, in _execute_callable
    return ExecutionCallableRunner(
           ^^^^^^^^^^^^^^^^^^^^^^^^
  File "/home/airflow/.local/lib/python3.12/site-packages/airflow/utils/operator_helpers.py", line 252, in run
    return self.func(*args, **kwargs)
           ^^^^^^^^^^^^^^^^^^^^^^^^^^
  File "/home/airflow/.local/lib/python3.12/site-packages/airflow/models/baseoperator.py", line 424, in wrapper
    return func(self, *args, **kwargs)
           ^^^^^^^^^^^^^^^^^^^^^^^^^^^
  File "/home/airflow/.local/lib/python3.12/site-packages/airflow/providers/http/operators/http.py", line 177, in execute
    return self.execute_sync(context=context)
           ^^^^^^^^^^^^^^^^^^^^^^^^^^^^^^^^^^
  File "/home/airflow/.local/lib/python3.12/site-packages/airflow/providers/http/operators/http.py", line 191, in execute_sync
    response = self.hook.run(
               ^^^^^^^^^^^^^^
  File "/home/airflow/.local/lib/python3.12/site-packages/airflow/providers/http/hooks/http.py", line 265, in run
    return self.run_and_check(session, prepped_request, extra_options)
           ^^^^^^^^^^^^^^^^^^^^^^^^^^^^^^^^^^^^^^^^^^^^^^^^^^^^^^^^^^^
  File "/home/airflow/.local/lib/python3.12/site-packages/airflow/providers/http/hooks/http.py", line 318, in run_and_check
    self.check_response(response)
  File "/home/airflow/.local/lib/python3.12/site-packages/airflow/providers/http/hooks/http.py", line 280, in check_response
    raise AirflowException(str(response.status_code) + ":" + response.reason)
airflow.exceptions.AirflowException: 409:Conflict
[2025-04-07T11:27:56.556+0000] {logging_mixin.py:190} INFO - Task instance in failure state
[2025-04-07T11:27:56.557+0000] {logging_mixin.py:190} INFO - Task start:2025-04-07 11:27:56.351287+00:00 end:2025-04-07 11:27:56.556300+00:00 duration:0.205013
[2025-04-07T11:27:56.557+0000] {logging_mixin.py:190} INFO - Task:<Task(HttpOperator): airbyte_sync.trigger_connection_sync> dag:<DAG: meta_ads_elt_pipeline> dagrun:<DagRun meta_ads_elt_pipeline @ 2025-04-07 11:27:54.573381+00:00: manual__2025-04-07T11:27:54.573381+00:00, state:running, queued_at: 2025-04-07 11:27:54.588070+00:00. externally triggered: True>
[2025-04-07T11:27:56.558+0000] {logging_mixin.py:190} INFO - Failure caused by 409:Conflict
[2025-04-07T11:27:56.558+0000] {taskinstance.py:1226} INFO - Marking task as UP_FOR_RETRY. dag_id=meta_ads_elt_pipeline, task_id=airbyte_sync.trigger_connection_sync, run_id=manual__2025-04-07T11:27:54.573381+00:00, execution_date=20250407T112754, start_date=20250407T112756, end_date=20250407T112756
[2025-04-07T11:27:56.589+0000] {taskinstance.py:341} INFO - ::group::Post task execution logs
[2025-04-07T11:27:56.589+0000] {standard_task_runner.py:124} ERROR - Failed to execute job 109 for task airbyte_sync.trigger_connection_sync (409:Conflict; 3173)
Traceback (most recent call last):
  File "/home/airflow/.local/lib/python3.12/site-packages/airflow/providers/http/hooks/http.py", line 276, in check_response
    response.raise_for_status()
  File "/home/airflow/.local/lib/python3.12/site-packages/requests/models.py", line 1024, in raise_for_status
    raise HTTPError(http_error_msg, response=self)
requests.exceptions.HTTPError: 409 Client Error: Conflict for url: http://192.168.1.130:8000/api/v1/connections/sync

During handling of the above exception, another exception occurred:

Traceback (most recent call last):
  File "/home/airflow/.local/lib/python3.12/site-packages/airflow/task/task_runner/standard_task_runner.py", line 117, in _start_by_fork
    ret = args.func(args, dag=self.dag)
          ^^^^^^^^^^^^^^^^^^^^^^^^^^^^^
  File "/home/airflow/.local/lib/python3.12/site-packages/airflow/cli/cli_config.py", line 49, in command
    return func(*args, **kwargs)
           ^^^^^^^^^^^^^^^^^^^^^
  File "/home/airflow/.local/lib/python3.12/site-packages/airflow/utils/cli.py", line 116, in wrapper
    return f(*args, **kwargs)
           ^^^^^^^^^^^^^^^^^^
  File "/home/airflow/.local/lib/python3.12/site-packages/airflow/cli/commands/task_command.py", line 483, in task_run
    task_return_code = _run_task_by_selected_method(args, _dag, ti)
                       ^^^^^^^^^^^^^^^^^^^^^^^^^^^^^^^^^^^^^^^^^^^^
  File "/home/airflow/.local/lib/python3.12/site-packages/airflow/cli/commands/task_command.py", line 256, in _run_task_by_selected_method
    return _run_raw_task(args, ti)
           ^^^^^^^^^^^^^^^^^^^^^^^
  File "/home/airflow/.local/lib/python3.12/site-packages/airflow/cli/commands/task_command.py", line 341, in _run_raw_task
    return ti._run_raw_task(
           ^^^^^^^^^^^^^^^^^
  File "/home/airflow/.local/lib/python3.12/site-packages/airflow/utils/session.py", line 97, in wrapper
    return func(*args, session=session, **kwargs)
           ^^^^^^^^^^^^^^^^^^^^^^^^^^^^^^^^^^^^^^
  File "/home/airflow/.local/lib/python3.12/site-packages/airflow/models/taskinstance.py", line 3006, in _run_raw_task
    return _run_raw_task(
           ^^^^^^^^^^^^^^
  File "/home/airflow/.local/lib/python3.12/site-packages/airflow/models/taskinstance.py", line 274, in _run_raw_task
    TaskInstance._execute_task_with_callbacks(
  File "/home/airflow/.local/lib/python3.12/site-packages/airflow/models/taskinstance.py", line 3161, in _execute_task_with_callbacks
    result = self._execute_task(context, task_orig)
             ^^^^^^^^^^^^^^^^^^^^^^^^^^^^^^^^^^^^^^
  File "/home/airflow/.local/lib/python3.12/site-packages/airflow/models/taskinstance.py", line 3185, in _execute_task
    return _execute_task(self, context, task_orig)
           ^^^^^^^^^^^^^^^^^^^^^^^^^^^^^^^^^^^^^^^
  File "/home/airflow/.local/lib/python3.12/site-packages/airflow/models/taskinstance.py", line 768, in _execute_task
    result = _execute_callable(context=context, **execute_callable_kwargs)
             ^^^^^^^^^^^^^^^^^^^^^^^^^^^^^^^^^^^^^^^^^^^^^^^^^^^^^^^^^^^^^
  File "/home/airflow/.local/lib/python3.12/site-packages/airflow/models/taskinstance.py", line 734, in _execute_callable
    return ExecutionCallableRunner(
           ^^^^^^^^^^^^^^^^^^^^^^^^
  File "/home/airflow/.local/lib/python3.12/site-packages/airflow/utils/operator_helpers.py", line 252, in run
    return self.func(*args, **kwargs)
           ^^^^^^^^^^^^^^^^^^^^^^^^^^
  File "/home/airflow/.local/lib/python3.12/site-packages/airflow/models/baseoperator.py", line 424, in wrapper
    return func(self, *args, **kwargs)
           ^^^^^^^^^^^^^^^^^^^^^^^^^^^
  File "/home/airflow/.local/lib/python3.12/site-packages/airflow/providers/http/operators/http.py", line 177, in execute
    return self.execute_sync(context=context)
           ^^^^^^^^^^^^^^^^^^^^^^^^^^^^^^^^^^
  File "/home/airflow/.local/lib/python3.12/site-packages/airflow/providers/http/operators/http.py", line 191, in execute_sync
    response = self.hook.run(
               ^^^^^^^^^^^^^^
  File "/home/airflow/.local/lib/python3.12/site-packages/airflow/providers/http/hooks/http.py", line 265, in run
    return self.run_and_check(session, prepped_request, extra_options)
           ^^^^^^^^^^^^^^^^^^^^^^^^^^^^^^^^^^^^^^^^^^^^^^^^^^^^^^^^^^^
  File "/home/airflow/.local/lib/python3.12/site-packages/airflow/providers/http/hooks/http.py", line 318, in run_and_check
    self.check_response(response)
  File "/home/airflow/.local/lib/python3.12/site-packages/airflow/providers/http/hooks/http.py", line 280, in check_response
    raise AirflowException(str(response.status_code) + ":" + response.reason)
airflow.exceptions.AirflowException: 409:Conflict
[2025-04-07T11:27:56.637+0000] {local_task_job_runner.py:266} INFO - Task exited with return code 1
[2025-04-07T11:27:56.670+0000] {taskinstance.py:3901} INFO - 0 downstream tasks scheduled from follow-on schedule check
[2025-04-07T11:27:56.671+0000] {local_task_job_runner.py:245} INFO - ::endgroup::
