[2025-03-26T18:32:16.985+0000] {local_task_job_runner.py:123} INFO - ::group::Pre task execution logs
[2025-03-26T18:32:17.002+0000] {taskinstance.py:2614} INFO - Dependencies all met for dep_context=non-requeueable deps ti=<TaskInstance: Airbyte-Dag.airbyte_money_json_example scheduled__2025-03-25T00:00:00+00:00 [queued]>
[2025-03-26T18:32:17.008+0000] {taskinstance.py:2614} INFO - Dependencies all met for dep_context=requeueable deps ti=<TaskInstance: Airbyte-Dag.airbyte_money_json_example scheduled__2025-03-25T00:00:00+00:00 [queued]>
[2025-03-26T18:32:17.008+0000] {taskinstance.py:2867} INFO - Starting attempt 1 of 1
[2025-03-26T18:32:17.019+0000] {taskinstance.py:2890} INFO - Executing <Task(AirbyteTriggerSyncOperator): airbyte_money_json_example> on 2025-03-25 00:00:00+00:00
[2025-03-26T18:32:17.033+0000] {warnings.py:112} WARNING - /home/***/.local/lib/python3.12/site-packages/***/task/task_runner/standard_task_runner.py:70: DeprecationWarning: This process (pid=1598) is multi-threaded, use of fork() may lead to deadlocks in the child.
  pid = os.fork()

[2025-03-26T18:32:17.034+0000] {standard_task_runner.py:72} INFO - Started process 1601 to run task
[2025-03-26T18:32:17.037+0000] {standard_task_runner.py:104} INFO - Running: ['***', 'tasks', 'run', 'Airbyte-Dag', 'airbyte_money_json_example', 'scheduled__2025-03-25T00:00:00+00:00', '--job-id', '60', '--raw', '--subdir', 'DAGS_FOLDER/meta_ads_dag.py', '--cfg-path', '/tmp/tmpb9opuxnx']
[2025-03-26T18:32:17.038+0000] {standard_task_runner.py:105} INFO - Job 60: Subtask airbyte_money_json_example
[2025-03-26T18:32:17.084+0000] {task_command.py:467} INFO - Running <TaskInstance: Airbyte-Dag.airbyte_money_json_example scheduled__2025-03-25T00:00:00+00:00 [running]> on host 929e032a3063
[2025-03-26T18:32:17.148+0000] {taskinstance.py:3134} INFO - Exporting env vars: AIRFLOW_CTX_DAG_OWNER='Rajesh' AIRFLOW_CTX_DAG_ID='Airbyte-Dag' AIRFLOW_CTX_TASK_ID='airbyte_money_json_example' AIRFLOW_CTX_EXECUTION_DATE='2025-03-25T00:00:00+00:00' AIRFLOW_CTX_TRY_NUMBER='1' AIRFLOW_CTX_DAG_RUN_ID='scheduled__2025-03-25T00:00:00+00:00'
[2025-03-26T18:32:17.150+0000] {logging_mixin.py:190} INFO - Task instance is in running state
[2025-03-26T18:32:17.150+0000] {logging_mixin.py:190} INFO -  Previous state of the Task instance: queued
[2025-03-26T18:32:17.151+0000] {logging_mixin.py:190} INFO - Current task name:airbyte_money_json_example state:running start_date:2025-03-26 18:32:17.003252+00:00
[2025-03-26T18:32:17.151+0000] {logging_mixin.py:190} INFO - Dag name:Airbyte-Dag and current dag run status:running
[2025-03-26T18:32:17.151+0000] {taskinstance.py:732} INFO - ::endgroup::
[2025-03-26T18:32:17.160+0000] {base.py:84} INFO - Retrieving connection 'airbyte'
[2025-03-26T18:32:17.174+0000] {taskinstance.py:3313} ERROR - Task failed with exception
Traceback (most recent call last):
  File "/home/airflow/.local/lib/python3.12/site-packages/airflow/providers/airbyte/hooks/airbyte.py", line 157, in submit_sync_connection
    res = self.airbyte_api.jobs.create_job(
          ^^^^^^^^^^^^^^^^^^^^^^^^^^^^^^^^^
  File "/home/airflow/.local/lib/python3.12/site-packages/airbyte_api/jobs.py", line 100, in create_job
    raise e
  File "/home/airflow/.local/lib/python3.12/site-packages/airbyte_api/jobs.py", line 95, in create_job
    req = self.sdk_configuration.get_hooks().before_request(BeforeRequestContext(hook_ctx), req)
          ^^^^^^^^^^^^^^^^^^^^^^^^^^^^^^^^^^^^^^^^^^^^^^^^^^^^^^^^^^^^^^^^^^^^^^^^^^^^^^^^^^^^^^
  File "/home/airflow/.local/lib/python3.12/site-packages/airbyte_api/_hooks/sdkhooks.py", line 41, in before_request
    out = hook.before_request(hook_ctx, request)
          ^^^^^^^^^^^^^^^^^^^^^^^^^^^^^^^^^^^^^^
  File "/home/airflow/.local/lib/python3.12/site-packages/airbyte_api/_hooks/clientcredentials.py", line 59, in before_request
    sess = self.do_token_request(credentials, self.get_scopes(
           ^^^^^^^^^^^^^^^^^^^^^^^^^^^^^^^^^^^^^^^^^^^^^^^^^^^
  File "/home/airflow/.local/lib/python3.12/site-packages/airbyte_api/_hooks/clientcredentials.py", line 119, in do_token_request
    response = self.client.post(token_url, data=payload)
               ^^^^^^^^^^^^^^^^^^^^^^^^^^^^^^^^^^^^^^^^^
  File "/home/airflow/.local/lib/python3.12/site-packages/requests/sessions.py", line 637, in post
    return self.request("POST", url, data=data, json=json, **kwargs)
           ^^^^^^^^^^^^^^^^^^^^^^^^^^^^^^^^^^^^^^^^^^^^^^^^^^^^^^^^^
  File "/home/airflow/.local/lib/python3.12/site-packages/requests/sessions.py", line 575, in request
    prep = self.prepare_request(req)
           ^^^^^^^^^^^^^^^^^^^^^^^^^
  File "/home/airflow/.local/lib/python3.12/site-packages/requests/sessions.py", line 484, in prepare_request
    p.prepare(
  File "/home/airflow/.local/lib/python3.12/site-packages/requests/models.py", line 367, in prepare
    self.prepare_url(url, params)
  File "/home/airflow/.local/lib/python3.12/site-packages/requests/models.py", line 438, in prepare_url
    raise MissingSchema(
requests.exceptions.MissingSchema: Invalid URL 'v1/applications/token': No scheme supplied. Perhaps you meant https://v1/applications/token?

During handling of the above exception, another exception occurred:

Traceback (most recent call last):
  File "/home/airflow/.local/lib/python3.12/site-packages/airflow/models/taskinstance.py", line 768, in _execute_task
    result = _execute_callable(context=context, **execute_callable_kwargs)
             ^^^^^^^^^^^^^^^^^^^^^^^^^^^^^^^^^^^^^^^^^^^^^^^^^^^^^^^^^^^^^
  File "/home/airflow/.local/lib/python3.12/site-packages/airflow/models/taskinstance.py", line 734, in _execute_callable
    return ExecutionCallableRunner(
           ^^^^^^^^^^^^^^^^^^^^^^^^
  File "/home/airflow/.local/lib/python3.12/site-packages/airflow/utils/operator_helpers.py", line 252, in run
    return self.func(*args, **kwargs)
           ^^^^^^^^^^^^^^^^^^^^^^^^^^
  File "/home/airflow/.local/lib/python3.12/site-packages/airflow/models/baseoperator.py", line 424, in wrapper
    return func(self, *args, **kwargs)
           ^^^^^^^^^^^^^^^^^^^^^^^^^^^
  File "/home/airflow/.local/lib/python3.12/site-packages/airflow/providers/airbyte/operators/airbyte.py", line 84, in execute
    job_object = hook.submit_sync_connection(connection_id=self.connection_id)
                 ^^^^^^^^^^^^^^^^^^^^^^^^^^^^^^^^^^^^^^^^^^^^^^^^^^^^^^^^^^^^^
  File "/home/airflow/.local/lib/python3.12/site-packages/airflow/providers/airbyte/hooks/airbyte.py", line 165, in submit_sync_connection
    raise AirflowException(e)
airflow.exceptions.AirflowException: Invalid URL 'v1/applications/token': No scheme supplied. Perhaps you meant https://v1/applications/token?
[2025-03-26T18:32:17.179+0000] {logging_mixin.py:190} INFO - Task instance in failure state
[2025-03-26T18:32:17.179+0000] {logging_mixin.py:190} INFO - Task start:2025-03-26 18:32:17.003252+00:00 end:2025-03-26 18:32:17.178939+00:00 duration:0.175687
[2025-03-26T18:32:17.179+0000] {logging_mixin.py:190} INFO - Task:<Task(AirbyteTriggerSyncOperator): airbyte_money_json_example> dag:<DAG: Airbyte-Dag> dagrun:<DagRun Airbyte-Dag @ 2025-03-25 00:00:00+00:00: scheduled__2025-03-25T00:00:00+00:00, state:running, queued_at: 2025-03-26 18:32:14.851061+00:00. externally triggered: False>
[2025-03-26T18:32:17.179+0000] {logging_mixin.py:190} INFO - Failure caused by Invalid URL 'v1/applications/token': No scheme supplied. Perhaps you meant https://v1/applications/token?
[2025-03-26T18:32:17.180+0000] {taskinstance.py:1226} INFO - Marking task as FAILED. dag_id=Airbyte-Dag, task_id=airbyte_money_json_example, run_id=scheduled__2025-03-25T00:00:00+00:00, execution_date=20250325T000000, start_date=20250326T183217, end_date=20250326T183217
[2025-03-26T18:32:17.204+0000] {taskinstance.py:341} INFO - ::group::Post task execution logs
[2025-03-26T18:32:17.204+0000] {standard_task_runner.py:124} ERROR - Failed to execute job 60 for task airbyte_money_json_example (Invalid URL 'v1/applications/token': No scheme supplied. Perhaps you meant https://v1/applications/token?; 1601)
Traceback (most recent call last):
  File "/home/airflow/.local/lib/python3.12/site-packages/airflow/providers/airbyte/hooks/airbyte.py", line 157, in submit_sync_connection
    res = self.airbyte_api.jobs.create_job(
          ^^^^^^^^^^^^^^^^^^^^^^^^^^^^^^^^^
  File "/home/airflow/.local/lib/python3.12/site-packages/airbyte_api/jobs.py", line 100, in create_job
    raise e
  File "/home/airflow/.local/lib/python3.12/site-packages/airbyte_api/jobs.py", line 95, in create_job
    req = self.sdk_configuration.get_hooks().before_request(BeforeRequestContext(hook_ctx), req)
          ^^^^^^^^^^^^^^^^^^^^^^^^^^^^^^^^^^^^^^^^^^^^^^^^^^^^^^^^^^^^^^^^^^^^^^^^^^^^^^^^^^^^^^
  File "/home/airflow/.local/lib/python3.12/site-packages/airbyte_api/_hooks/sdkhooks.py", line 41, in before_request
    out = hook.before_request(hook_ctx, request)
          ^^^^^^^^^^^^^^^^^^^^^^^^^^^^^^^^^^^^^^
  File "/home/airflow/.local/lib/python3.12/site-packages/airbyte_api/_hooks/clientcredentials.py", line 59, in before_request
    sess = self.do_token_request(credentials, self.get_scopes(
           ^^^^^^^^^^^^^^^^^^^^^^^^^^^^^^^^^^^^^^^^^^^^^^^^^^^
  File "/home/airflow/.local/lib/python3.12/site-packages/airbyte_api/_hooks/clientcredentials.py", line 119, in do_token_request
    response = self.client.post(token_url, data=payload)
               ^^^^^^^^^^^^^^^^^^^^^^^^^^^^^^^^^^^^^^^^^
  File "/home/airflow/.local/lib/python3.12/site-packages/requests/sessions.py", line 637, in post
    return self.request("POST", url, data=data, json=json, **kwargs)
           ^^^^^^^^^^^^^^^^^^^^^^^^^^^^^^^^^^^^^^^^^^^^^^^^^^^^^^^^^
  File "/home/airflow/.local/lib/python3.12/site-packages/requests/sessions.py", line 575, in request
    prep = self.prepare_request(req)
           ^^^^^^^^^^^^^^^^^^^^^^^^^
  File "/home/airflow/.local/lib/python3.12/site-packages/requests/sessions.py", line 484, in prepare_request
    p.prepare(
  File "/home/airflow/.local/lib/python3.12/site-packages/requests/models.py", line 367, in prepare
    self.prepare_url(url, params)
  File "/home/airflow/.local/lib/python3.12/site-packages/requests/models.py", line 438, in prepare_url
    raise MissingSchema(
requests.exceptions.MissingSchema: Invalid URL 'v1/applications/token': No scheme supplied. Perhaps you meant https://v1/applications/token?

During handling of the above exception, another exception occurred:

Traceback (most recent call last):
  File "/home/airflow/.local/lib/python3.12/site-packages/airflow/task/task_runner/standard_task_runner.py", line 117, in _start_by_fork
    ret = args.func(args, dag=self.dag)
          ^^^^^^^^^^^^^^^^^^^^^^^^^^^^^
  File "/home/airflow/.local/lib/python3.12/site-packages/airflow/cli/cli_config.py", line 49, in command
    return func(*args, **kwargs)
           ^^^^^^^^^^^^^^^^^^^^^
  File "/home/airflow/.local/lib/python3.12/site-packages/airflow/utils/cli.py", line 116, in wrapper
    return f(*args, **kwargs)
           ^^^^^^^^^^^^^^^^^^
  File "/home/airflow/.local/lib/python3.12/site-packages/airflow/cli/commands/task_command.py", line 483, in task_run
    task_return_code = _run_task_by_selected_method(args, _dag, ti)
                       ^^^^^^^^^^^^^^^^^^^^^^^^^^^^^^^^^^^^^^^^^^^^
  File "/home/airflow/.local/lib/python3.12/site-packages/airflow/cli/commands/task_command.py", line 256, in _run_task_by_selected_method
    return _run_raw_task(args, ti)
           ^^^^^^^^^^^^^^^^^^^^^^^
  File "/home/airflow/.local/lib/python3.12/site-packages/airflow/cli/commands/task_command.py", line 341, in _run_raw_task
    return ti._run_raw_task(
           ^^^^^^^^^^^^^^^^^
  File "/home/airflow/.local/lib/python3.12/site-packages/airflow/utils/session.py", line 97, in wrapper
    return func(*args, session=session, **kwargs)
           ^^^^^^^^^^^^^^^^^^^^^^^^^^^^^^^^^^^^^^
  File "/home/airflow/.local/lib/python3.12/site-packages/airflow/models/taskinstance.py", line 3006, in _run_raw_task
    return _run_raw_task(
           ^^^^^^^^^^^^^^
  File "/home/airflow/.local/lib/python3.12/site-packages/airflow/models/taskinstance.py", line 274, in _run_raw_task
    TaskInstance._execute_task_with_callbacks(
  File "/home/airflow/.local/lib/python3.12/site-packages/airflow/models/taskinstance.py", line 3161, in _execute_task_with_callbacks
    result = self._execute_task(context, task_orig)
             ^^^^^^^^^^^^^^^^^^^^^^^^^^^^^^^^^^^^^^
  File "/home/airflow/.local/lib/python3.12/site-packages/airflow/models/taskinstance.py", line 3185, in _execute_task
    return _execute_task(self, context, task_orig)
           ^^^^^^^^^^^^^^^^^^^^^^^^^^^^^^^^^^^^^^^
  File "/home/airflow/.local/lib/python3.12/site-packages/airflow/models/taskinstance.py", line 768, in _execute_task
    result = _execute_callable(context=context, **execute_callable_kwargs)
             ^^^^^^^^^^^^^^^^^^^^^^^^^^^^^^^^^^^^^^^^^^^^^^^^^^^^^^^^^^^^^
  File "/home/airflow/.local/lib/python3.12/site-packages/airflow/models/taskinstance.py", line 734, in _execute_callable
    return ExecutionCallableRunner(
           ^^^^^^^^^^^^^^^^^^^^^^^^
  File "/home/airflow/.local/lib/python3.12/site-packages/airflow/utils/operator_helpers.py", line 252, in run
    return self.func(*args, **kwargs)
           ^^^^^^^^^^^^^^^^^^^^^^^^^^
  File "/home/airflow/.local/lib/python3.12/site-packages/airflow/models/baseoperator.py", line 424, in wrapper
    return func(self, *args, **kwargs)
           ^^^^^^^^^^^^^^^^^^^^^^^^^^^
  File "/home/airflow/.local/lib/python3.12/site-packages/airflow/providers/airbyte/operators/airbyte.py", line 84, in execute
    job_object = hook.submit_sync_connection(connection_id=self.connection_id)
                 ^^^^^^^^^^^^^^^^^^^^^^^^^^^^^^^^^^^^^^^^^^^^^^^^^^^^^^^^^^^^^
  File "/home/airflow/.local/lib/python3.12/site-packages/airflow/providers/airbyte/hooks/airbyte.py", line 165, in submit_sync_connection
    raise AirflowException(e)
airflow.exceptions.AirflowException: Invalid URL 'v1/applications/token': No scheme supplied. Perhaps you meant https://v1/applications/token?
[2025-03-26T18:32:17.248+0000] {local_task_job_runner.py:266} INFO - Task exited with return code 1
[2025-03-26T18:32:17.283+0000] {taskinstance.py:3901} INFO - 0 downstream tasks scheduled from follow-on schedule check
[2025-03-26T18:32:17.287+0000] {local_task_job_runner.py:245} INFO - ::endgroup::
