[2025-04-07T19:26:32.101+0000] {local_task_job_runner.py:123} INFO - ::group::Pre task execution logs
[2025-04-07T19:26:32.119+0000] {taskinstance.py:2614} INFO - Dependencies all met for dep_context=non-requeueable deps ti=<TaskInstance: meta_ads_elt_pipeline.dbt_processing.data_transformations.meta_ads_ad_sets_run manual__2025-04-07T19:25:23.652910+00:00 [queued]>
[2025-04-07T19:26:32.126+0000] {taskinstance.py:2614} INFO - Dependencies all met for dep_context=requeueable deps ti=<TaskInstance: meta_ads_elt_pipeline.dbt_processing.data_transformations.meta_ads_ad_sets_run manual__2025-04-07T19:25:23.652910+00:00 [queued]>
[2025-04-07T19:26:32.127+0000] {taskinstance.py:2867} INFO - Starting attempt 1 of 3
[2025-04-07T19:26:32.137+0000] {taskinstance.py:2890} INFO - Executing <Task(DbtRunLocalOperator): dbt_processing.data_transformations.meta_ads_ad_sets_run> on 2025-04-07 19:25:23.652910+00:00
[2025-04-07T19:26:32.150+0000] {warnings.py:112} WARNING - /home/***/.local/lib/python3.12/site-packages/***/task/task_runner/standard_task_runner.py:70: DeprecationWarning: This process (pid=3020) is multi-threaded, use of fork() may lead to deadlocks in the child.
  pid = os.fork()

[2025-04-07T19:26:32.151+0000] {standard_task_runner.py:72} INFO - Started process 3032 to run task
[2025-04-07T19:26:32.154+0000] {standard_task_runner.py:104} INFO - Running: ['***', 'tasks', 'run', 'meta_ads_elt_pipeline', 'dbt_processing.data_transformations.meta_ads_ad_sets_run', 'manual__2025-04-07T19:25:23.652910+00:00', '--job-id', '206', '--raw', '--subdir', 'DAGS_FOLDER/meta_ads_dag.py', '--cfg-path', '/tmp/tmpwjwxscj4']
[2025-04-07T19:26:32.155+0000] {standard_task_runner.py:105} INFO - Job 206: Subtask dbt_processing.data_transformations.meta_ads_ad_sets_run
[2025-04-07T19:26:32.201+0000] {task_command.py:467} INFO - Running <TaskInstance: meta_ads_elt_pipeline.dbt_processing.data_transformations.meta_ads_ad_sets_run manual__2025-04-07T19:25:23.652910+00:00 [running]> on host ffa99f2ae5fe
[2025-04-07T19:26:32.286+0000] {taskinstance.py:3134} INFO - Exporting env vars: AIRFLOW_CTX_DAG_OWNER='admin' AIRFLOW_CTX_DAG_ID='meta_ads_elt_pipeline' AIRFLOW_CTX_TASK_ID='dbt_processing.data_transformations.meta_ads_ad_sets_run' AIRFLOW_CTX_EXECUTION_DATE='2025-04-07T19:25:23.652910+00:00' AIRFLOW_CTX_TRY_NUMBER='1' AIRFLOW_CTX_DAG_RUN_ID='manual__2025-04-07T19:25:23.652910+00:00'
[2025-04-07T19:26:32.288+0000] {logging_mixin.py:190} INFO - Task instance is in running state
[2025-04-07T19:26:32.288+0000] {logging_mixin.py:190} INFO -  Previous state of the Task instance: queued
[2025-04-07T19:26:32.289+0000] {logging_mixin.py:190} INFO - Current task name:dbt_processing.data_transformations.meta_ads_ad_sets_run state:running start_date:2025-04-07 19:26:32.119594+00:00
[2025-04-07T19:26:32.289+0000] {logging_mixin.py:190} INFO - Dag name:meta_ads_elt_pipeline and current dag run status:running
[2025-04-07T19:26:32.289+0000] {taskinstance.py:732} INFO - ::endgroup::
[2025-04-07T19:26:33.338+0000] {local.py:213} INFO - dbtRunner is available. Using dbtRunner for invoking dbt.
[2025-04-07T19:26:33.338+0000] {local.py:416} INFO - Cloning project to writable temp directory /tmp/tmpim0v6fzs from /opt/airflow/dags/dbt/dbt_biera
[2025-04-07T19:26:33.339+0000] {local.py:427} INFO - Partial parse is enabled and the latest partial parse file is /tmp/cosmos/meta_ads_elt_pipeline__dbt_processing__data_transformations/target/partial_parse.msgpack
[2025-04-07T19:26:33.346+0000] {config.py:360} INFO - Profile caching is enable.
[2025-04-07T19:26:33.355+0000] {base.py:84} INFO - Retrieving connection 'postgres_conn'
[2025-04-07T19:26:33.356+0000] {config.py:340} INFO - Profile found in cache using profile: /tmp/cosmos/profile/c99bf486c96f06e0233408d45300d7cde96c22a7e21e1f49350115e2a86b810b/profiles.yml.
[2025-04-07T19:26:33.356+0000] {runner.py:60} INFO - Trying to run dbtRunner with:
 ['run', '--select', 'meta_ads_campaigns meta_ads_ad_sets meta_ads_ads', '--models', 'meta_ads_ad_sets', '--full-refresh', '--project-dir', '/tmp/tmpim0v6fzs', '--profiles-dir', '/tmp/cosmos/profile/c99bf486c96f06e0233408d45300d7cde96c22a7e21e1f49350115e2a86b810b', '--profile', 'default', '--target', 'dev']
 in /tmp/tmpim0v6fzs
[2025-04-07T19:26:33.424+0000] {logging_mixin.py:190} INFO - 19:26:33  Running with dbt=1.9.3
[2025-04-07T19:26:33.650+0000] {logging_mixin.py:190} INFO - 19:26:33  Registered adapter: postgres=1.9.0
[2025-04-07T19:26:34.608+0000] {logging_mixin.py:190} INFO - 19:26:34  [WARNING]: Configuration paths exist in your dbt_project.yml file which do not apply to any resources.
There are 1 unused configuration paths:
- models.dbt_biera.analytics
[2025-04-07T19:26:34.737+0000] {logging_mixin.py:190} INFO - 19:26:34  Found 4 models, 4 sources, 434 macros
[2025-04-07T19:26:34.739+0000] {logging_mixin.py:190} INFO - 19:26:34
[2025-04-07T19:26:34.740+0000] {logging_mixin.py:190} INFO - 19:26:34  Concurrency: 1 threads (target='dev')
[2025-04-07T19:26:34.741+0000] {logging_mixin.py:190} INFO - 19:26:34
[2025-04-07T19:26:34.827+0000] {logging_mixin.py:190} INFO - 19:26:34  1 of 3 START sql view model staging.meta_ads_ad_sets ........................... [RUN]
[2025-04-07T19:26:34.941+0000] {logging_mixin.py:190} INFO - 19:26:34  1 of 3 OK created sql view model staging.meta_ads_ad_sets ...................... [CREATE VIEW in 0.11s]
[2025-04-07T19:26:34.943+0000] {logging_mixin.py:190} INFO - 19:26:34  2 of 3 START sql view model staging.meta_ads_ads ............................... [RUN]
[2025-04-07T19:26:34.979+0000] {logging_mixin.py:190} INFO - 19:26:34  2 of 3 ERROR creating sql view model staging.meta_ads_ads ...................... [ERROR in 0.03s]
[2025-04-07T19:26:34.981+0000] {logging_mixin.py:190} INFO - 19:26:34  3 of 3 START sql view model staging.meta_ads_campaigns ......................... [RUN]
[2025-04-07T19:26:35.022+0000] {logging_mixin.py:190} INFO - 19:26:35  3 of 3 OK created sql view model staging.meta_ads_campaigns .................... [CREATE VIEW in 0.04s]
[2025-04-07T19:26:35.037+0000] {logging_mixin.py:190} INFO - 19:26:35
[2025-04-07T19:26:35.039+0000] {logging_mixin.py:190} INFO - 19:26:35  Finished running 3 view models in 0 hours 0 minutes and 0.30 seconds (0.30s).
[2025-04-07T19:26:35.085+0000] {logging_mixin.py:190} INFO - 19:26:35
[2025-04-07T19:26:35.086+0000] {logging_mixin.py:190} INFO - 19:26:35  Completed with 1 error, 0 partial successes, and 0 warnings:
[2025-04-07T19:26:35.087+0000] {logging_mixin.py:190} INFO - 19:26:35
[2025-04-07T19:26:35.087+0000] {logging_mixin.py:190} INFO - 19:26:35    Database Error in model meta_ads_ads (models/staging/meta_ads/meta_ads_ads.sql)
  relation "meta_ads_ads" already exists
  compiled code at target/run/dbt_biera/models/staging/meta_ads/meta_ads_ads.sql
[2025-04-07T19:26:35.088+0000] {logging_mixin.py:190} INFO - 19:26:35
[2025-04-07T19:26:35.088+0000] {logging_mixin.py:190} INFO - 19:26:35  Done. PASS=2 WARN=0 ERROR=1 SKIP=0 TOTAL=3
[2025-04-07T19:26:35.657+0000] {warnings.py:112} WARNING - /home/***/.local/lib/python3.12/site-packages/cosmos/operators/local.py:616: UserWarning: The dataset URI postgres://postgres:5432/warehouse.source.meta_ads_ad_sets is not AIP-60 compliant: URI format postgres:// must contain database, schema, and table names. In Airflow 3, this will raise an exception.
  datasets = [Dataset(uri) for uri in uris]

[2025-04-07T19:26:35.658+0000] {warnings.py:112} WARNING - /home/***/.local/lib/python3.12/site-packages/cosmos/operators/local.py:616: UserWarning: The dataset URI postgres://postgres:5432/warehouse.source.meta_ads_campaigns is not AIP-60 compliant: URI format postgres:// must contain database, schema, and table names. In Airflow 3, this will raise an exception.
  datasets = [Dataset(uri) for uri in uris]

[2025-04-07T19:26:35.658+0000] {warnings.py:112} WARNING - /home/***/.local/lib/python3.12/site-packages/cosmos/operators/local.py:616: UserWarning: The dataset URI postgres://postgres:5432/warehouse.staging.meta_ads_ad_sets is not AIP-60 compliant: URI format postgres:// must contain database, schema, and table names. In Airflow 3, this will raise an exception.
  datasets = [Dataset(uri) for uri in uris]

[2025-04-07T19:26:35.659+0000] {warnings.py:112} WARNING - /home/***/.local/lib/python3.12/site-packages/cosmos/operators/local.py:616: UserWarning: The dataset URI postgres://postgres:5432/warehouse.staging.meta_ads_campaigns is not AIP-60 compliant: URI format postgres:// must contain database, schema, and table names. In Airflow 3, this will raise an exception.
  datasets = [Dataset(uri) for uri in uris]

[2025-04-07T19:26:35.659+0000] {local.py:465} INFO - Inlets: [Dataset(uri='postgres://postgres:5432/warehouse.source.meta_ads_ad_sets', extra=None), Dataset(uri='postgres://postgres:5432/warehouse.source.meta_ads_campaigns', extra=None)]
[2025-04-07T19:26:35.659+0000] {local.py:466} INFO - Outlets: [Dataset(uri='postgres://postgres:5432/warehouse.staging.meta_ads_ad_sets', extra=None), Dataset(uri='postgres://postgres:5432/warehouse.staging.meta_ads_campaigns', extra=None)]
[2025-04-07T19:26:35.660+0000] {local.py:656} INFO - Assigning inlets/outlets with DatasetAlias
[2025-04-07T19:26:35.686+0000] {taskinstance.py:3313} ERROR - Task failed with exception
Traceback (most recent call last):
  File "/home/airflow/.local/lib/python3.12/site-packages/airflow/models/taskinstance.py", line 768, in _execute_task
    result = _execute_callable(context=context, **execute_callable_kwargs)
             ^^^^^^^^^^^^^^^^^^^^^^^^^^^^^^^^^^^^^^^^^^^^^^^^^^^^^^^^^^^^^
  File "/home/airflow/.local/lib/python3.12/site-packages/airflow/models/taskinstance.py", line 734, in _execute_callable
    return ExecutionCallableRunner(
           ^^^^^^^^^^^^^^^^^^^^^^^^
  File "/home/airflow/.local/lib/python3.12/site-packages/airflow/utils/operator_helpers.py", line 252, in run
    return self.func(*args, **kwargs)
           ^^^^^^^^^^^^^^^^^^^^^^^^^^
  File "/home/airflow/.local/lib/python3.12/site-packages/cosmos/operators/base.py", line 299, in execute
    self.build_and_run_cmd(context=context, cmd_flags=self.add_cmd_flags())
  File "/home/airflow/.local/lib/python3.12/site-packages/cosmos/operators/local.py", line 708, in build_and_run_cmd
    result = self.run_command(
             ^^^^^^^^^^^^^^^^^
  File "/home/airflow/.local/lib/python3.12/site-packages/cosmos/operators/local.py", line 556, in run_command
    self.handle_exception(result)
  File "/home/airflow/.local/lib/python3.12/site-packages/cosmos/operators/local.py", line 227, in handle_exception_dbt_runner
    return dbt_runner.handle_exception_if_needed(result)
           ^^^^^^^^^^^^^^^^^^^^^^^^^^^^^^^^^^^^^^^^^^^^^
  File "/home/airflow/.local/lib/python3.12/site-packages/cosmos/dbt/runner.py", line 113, in handle_exception_if_needed
    raise CosmosDbtRunError(f"dbt invocation completed with errors: {error_message}")
cosmos.exceptions.CosmosDbtRunError: dbt invocation completed with errors: meta_ads_ads: Database Error in model meta_ads_ads (models/staging/meta_ads/meta_ads_ads.sql)
  relation "meta_ads_ads" already exists
  compiled code at target/run/dbt_biera/models/staging/meta_ads/meta_ads_ads.sql
[2025-04-07T19:26:35.702+0000] {logging_mixin.py:190} INFO - Task instance in failure state
[2025-04-07T19:26:35.703+0000] {logging_mixin.py:190} INFO - Task start:2025-04-07 19:26:32.119594+00:00 end:2025-04-07 19:26:35.702030+00:00 duration:3.582436
[2025-04-07T19:26:35.703+0000] {logging_mixin.py:190} INFO - Task:<Task(DbtRunLocalOperator): dbt_processing.data_transformations.meta_ads_ad_sets_run> dag:<DAG: meta_ads_elt_pipeline> dagrun:<DagRun meta_ads_elt_pipeline @ 2025-04-07 19:25:23.652910+00:00: manual__2025-04-07T19:25:23.652910+00:00, state:running, queued_at: 2025-04-07 19:25:23.667195+00:00. externally triggered: True>
[2025-04-07T19:26:35.703+0000] {logging_mixin.py:190} INFO - Failure caused by dbt invocation completed with errors: meta_ads_ads: Database Error in model meta_ads_ads (models/staging/meta_ads/meta_ads_ads.sql)
  relation "meta_ads_ads" already exists
  compiled code at target/run/dbt_biera/models/staging/meta_ads/meta_ads_ads.sql
[2025-04-07T19:26:35.704+0000] {taskinstance.py:1226} INFO - Marking task as UP_FOR_RETRY. dag_id=meta_ads_elt_pipeline, task_id=dbt_processing.data_transformations.meta_ads_ad_sets_run, run_id=manual__2025-04-07T19:25:23.652910+00:00, execution_date=20250407T192523, start_date=20250407T192632, end_date=20250407T192635
[2025-04-07T19:26:35.738+0000] {taskinstance.py:341} INFO - ::group::Post task execution logs
[2025-04-07T19:26:35.739+0000] {standard_task_runner.py:124} ERROR - Failed to execute job 206 for task dbt_processing.data_transformations.meta_ads_ad_sets_run (dbt invocation completed with errors: meta_ads_ads: Database Error in model meta_ads_ads (models/staging/meta_ads/meta_ads_ads.sql)
  relation "meta_ads_ads" already exists
  compiled code at target/run/dbt_biera/models/staging/meta_ads/meta_ads_ads.sql; 3032)
Traceback (most recent call last):
  File "/home/airflow/.local/lib/python3.12/site-packages/airflow/task/task_runner/standard_task_runner.py", line 117, in _start_by_fork
    ret = args.func(args, dag=self.dag)
          ^^^^^^^^^^^^^^^^^^^^^^^^^^^^^
  File "/home/airflow/.local/lib/python3.12/site-packages/airflow/cli/cli_config.py", line 49, in command
    return func(*args, **kwargs)
           ^^^^^^^^^^^^^^^^^^^^^
  File "/home/airflow/.local/lib/python3.12/site-packages/airflow/utils/cli.py", line 116, in wrapper
    return f(*args, **kwargs)
           ^^^^^^^^^^^^^^^^^^
  File "/home/airflow/.local/lib/python3.12/site-packages/airflow/cli/commands/task_command.py", line 483, in task_run
    task_return_code = _run_task_by_selected_method(args, _dag, ti)
                       ^^^^^^^^^^^^^^^^^^^^^^^^^^^^^^^^^^^^^^^^^^^^
  File "/home/airflow/.local/lib/python3.12/site-packages/airflow/cli/commands/task_command.py", line 256, in _run_task_by_selected_method
    return _run_raw_task(args, ti)
           ^^^^^^^^^^^^^^^^^^^^^^^
  File "/home/airflow/.local/lib/python3.12/site-packages/airflow/cli/commands/task_command.py", line 341, in _run_raw_task
    return ti._run_raw_task(
           ^^^^^^^^^^^^^^^^^
  File "/home/airflow/.local/lib/python3.12/site-packages/airflow/utils/session.py", line 97, in wrapper
    return func(*args, session=session, **kwargs)
           ^^^^^^^^^^^^^^^^^^^^^^^^^^^^^^^^^^^^^^
  File "/home/airflow/.local/lib/python3.12/site-packages/airflow/models/taskinstance.py", line 3006, in _run_raw_task
    return _run_raw_task(
           ^^^^^^^^^^^^^^
  File "/home/airflow/.local/lib/python3.12/site-packages/airflow/models/taskinstance.py", line 274, in _run_raw_task
    TaskInstance._execute_task_with_callbacks(
  File "/home/airflow/.local/lib/python3.12/site-packages/airflow/models/taskinstance.py", line 3161, in _execute_task_with_callbacks
    result = self._execute_task(context, task_orig)
             ^^^^^^^^^^^^^^^^^^^^^^^^^^^^^^^^^^^^^^
  File "/home/airflow/.local/lib/python3.12/site-packages/airflow/models/taskinstance.py", line 3185, in _execute_task
    return _execute_task(self, context, task_orig)
           ^^^^^^^^^^^^^^^^^^^^^^^^^^^^^^^^^^^^^^^
  File "/home/airflow/.local/lib/python3.12/site-packages/airflow/models/taskinstance.py", line 768, in _execute_task
    result = _execute_callable(context=context, **execute_callable_kwargs)
             ^^^^^^^^^^^^^^^^^^^^^^^^^^^^^^^^^^^^^^^^^^^^^^^^^^^^^^^^^^^^^
  File "/home/airflow/.local/lib/python3.12/site-packages/airflow/models/taskinstance.py", line 734, in _execute_callable
    return ExecutionCallableRunner(
           ^^^^^^^^^^^^^^^^^^^^^^^^
  File "/home/airflow/.local/lib/python3.12/site-packages/airflow/utils/operator_helpers.py", line 252, in run
    return self.func(*args, **kwargs)
           ^^^^^^^^^^^^^^^^^^^^^^^^^^
  File "/home/airflow/.local/lib/python3.12/site-packages/cosmos/operators/base.py", line 299, in execute
    self.build_and_run_cmd(context=context, cmd_flags=self.add_cmd_flags())
  File "/home/airflow/.local/lib/python3.12/site-packages/cosmos/operators/local.py", line 708, in build_and_run_cmd
    result = self.run_command(
             ^^^^^^^^^^^^^^^^^
  File "/home/airflow/.local/lib/python3.12/site-packages/cosmos/operators/local.py", line 556, in run_command
    self.handle_exception(result)
  File "/home/airflow/.local/lib/python3.12/site-packages/cosmos/operators/local.py", line 227, in handle_exception_dbt_runner
    return dbt_runner.handle_exception_if_needed(result)
           ^^^^^^^^^^^^^^^^^^^^^^^^^^^^^^^^^^^^^^^^^^^^^
  File "/home/airflow/.local/lib/python3.12/site-packages/cosmos/dbt/runner.py", line 113, in handle_exception_if_needed
    raise CosmosDbtRunError(f"dbt invocation completed with errors: {error_message}")
cosmos.exceptions.CosmosDbtRunError: dbt invocation completed with errors: meta_ads_ads: Database Error in model meta_ads_ads (models/staging/meta_ads/meta_ads_ads.sql)
  relation "meta_ads_ads" already exists
  compiled code at target/run/dbt_biera/models/staging/meta_ads/meta_ads_ads.sql
[2025-04-07T19:26:35.814+0000] {local_task_job_runner.py:266} INFO - Task exited with return code 1
[2025-04-07T19:26:35.822+0000] {local_task_job_runner.py:245} INFO - ::endgroup::
