[2025-03-26T16:40:27.302+0000] {local_task_job_runner.py:123} INFO - ::group::Pre task execution logs
[2025-03-26T16:40:27.321+0000] {taskinstance.py:2614} INFO - Dependencies all met for dep_context=non-requeueable deps ti=<TaskInstance: trigger_airbyte_job_example.airbyte_metaads scheduled__2025-03-25T00:00:00+00:00 [queued]>
[2025-03-26T16:40:27.328+0000] {taskinstance.py:2614} INFO - Dependencies all met for dep_context=requeueable deps ti=<TaskInstance: trigger_airbyte_job_example.airbyte_metaads scheduled__2025-03-25T00:00:00+00:00 [queued]>
[2025-03-26T16:40:27.329+0000] {taskinstance.py:2867} INFO - Starting attempt 1 of 1
[2025-03-26T16:40:27.343+0000] {taskinstance.py:2890} INFO - Executing <Task(AirbyteTriggerSyncOperator): airbyte_metaads> on 2025-03-25 00:00:00+00:00
[2025-03-26T16:40:27.356+0000] {warnings.py:112} WARNING - /home/***/.local/lib/python3.12/site-packages/***/task/task_runner/standard_task_runner.py:70: DeprecationWarning: This process (pid=319) is multi-threaded, use of fork() may lead to deadlocks in the child.
  pid = os.fork()

[2025-03-26T16:40:27.358+0000] {standard_task_runner.py:72} INFO - Started process 348 to run task
[2025-03-26T16:40:27.360+0000] {standard_task_runner.py:104} INFO - Running: ['***', 'tasks', 'run', 'trigger_airbyte_job_example', 'airbyte_metaads', 'scheduled__2025-03-25T00:00:00+00:00', '--job-id', '22', '--raw', '--subdir', 'DAGS_FOLDER/meta_ads_dag.py', '--cfg-path', '/tmp/tmpkegzfg8p']
[2025-03-26T16:40:27.361+0000] {standard_task_runner.py:105} INFO - Job 22: Subtask airbyte_metaads
[2025-03-26T16:40:27.408+0000] {task_command.py:467} INFO - Running <TaskInstance: trigger_airbyte_job_example.airbyte_metaads scheduled__2025-03-25T00:00:00+00:00 [running]> on host e3e3ae5ea89f
[2025-03-26T16:40:27.490+0000] {taskinstance.py:3134} INFO - Exporting env vars: AIRFLOW_CTX_DAG_OWNER='***' AIRFLOW_CTX_DAG_ID='trigger_airbyte_job_example' AIRFLOW_CTX_TASK_ID='airbyte_metaads' AIRFLOW_CTX_EXECUTION_DATE='2025-03-25T00:00:00+00:00' AIRFLOW_CTX_TRY_NUMBER='1' AIRFLOW_CTX_DAG_RUN_ID='scheduled__2025-03-25T00:00:00+00:00'
[2025-03-26T16:40:27.492+0000] {logging_mixin.py:190} INFO - Task instance is in running state
[2025-03-26T16:40:27.492+0000] {logging_mixin.py:190} INFO -  Previous state of the Task instance: queued
[2025-03-26T16:40:27.492+0000] {logging_mixin.py:190} INFO - Current task name:airbyte_metaads state:running start_date:2025-03-26 16:40:27.321315+00:00
[2025-03-26T16:40:27.492+0000] {logging_mixin.py:190} INFO - Dag name:trigger_airbyte_job_example and current dag run status:running
[2025-03-26T16:40:27.492+0000] {taskinstance.py:732} INFO - ::endgroup::
[2025-03-26T16:40:27.502+0000] {base.py:84} INFO - Retrieving connection 'airbyte_conn'
[2025-03-26T16:40:27.518+0000] {taskinstance.py:3313} ERROR - Task failed with exception
Traceback (most recent call last):
  File "/home/airflow/.local/lib/python3.12/site-packages/airflow/providers/airbyte/hooks/airbyte.py", line 157, in submit_sync_connection
    res = self.airbyte_api.jobs.create_job(
          ^^^^^^^^^^^^^^^^^^^^^^^^^^^^^^^^^
  File "/home/airflow/.local/lib/python3.12/site-packages/airbyte_api/jobs.py", line 100, in create_job
    raise e
  File "/home/airflow/.local/lib/python3.12/site-packages/airbyte_api/jobs.py", line 94, in create_job
    req = client.prepare_request(requests_http.Request('POST', url, params=query_params, data=data, files=form, headers=headers))
          ^^^^^^^^^^^^^^^^^^^^^^^^^^^^^^^^^^^^^^^^^^^^^^^^^^^^^^^^^^^^^^^^^^^^^^^^^^^^^^^^^^^^^^^^^^^^^^^^^^^^^^^^^^^^^^^^^^^^^^^
  File "/home/airflow/.local/lib/python3.12/site-packages/requests/sessions.py", line 484, in prepare_request
    p.prepare(
  File "/home/airflow/.local/lib/python3.12/site-packages/requests/models.py", line 367, in prepare
    self.prepare_url(url, params)
  File "/home/airflow/.local/lib/python3.12/site-packages/requests/models.py", line 438, in prepare_url
    raise MissingSchema(
requests.exceptions.MissingSchema: Invalid URL 'docker.host.internal/jobs': No scheme supplied. Perhaps you meant https://docker.host.internal/jobs?

During handling of the above exception, another exception occurred:

Traceback (most recent call last):
  File "/home/airflow/.local/lib/python3.12/site-packages/airflow/models/taskinstance.py", line 768, in _execute_task
    result = _execute_callable(context=context, **execute_callable_kwargs)
             ^^^^^^^^^^^^^^^^^^^^^^^^^^^^^^^^^^^^^^^^^^^^^^^^^^^^^^^^^^^^^
  File "/home/airflow/.local/lib/python3.12/site-packages/airflow/models/taskinstance.py", line 734, in _execute_callable
    return ExecutionCallableRunner(
           ^^^^^^^^^^^^^^^^^^^^^^^^
  File "/home/airflow/.local/lib/python3.12/site-packages/airflow/utils/operator_helpers.py", line 252, in run
    return self.func(*args, **kwargs)
           ^^^^^^^^^^^^^^^^^^^^^^^^^^
  File "/home/airflow/.local/lib/python3.12/site-packages/airflow/models/baseoperator.py", line 424, in wrapper
    return func(self, *args, **kwargs)
           ^^^^^^^^^^^^^^^^^^^^^^^^^^^
  File "/home/airflow/.local/lib/python3.12/site-packages/airflow/providers/airbyte/operators/airbyte.py", line 84, in execute
    job_object = hook.submit_sync_connection(connection_id=self.connection_id)
                 ^^^^^^^^^^^^^^^^^^^^^^^^^^^^^^^^^^^^^^^^^^^^^^^^^^^^^^^^^^^^^
  File "/home/airflow/.local/lib/python3.12/site-packages/airflow/providers/airbyte/hooks/airbyte.py", line 165, in submit_sync_connection
    raise AirflowException(e)
airflow.exceptions.AirflowException: Invalid URL 'docker.host.internal/jobs': No scheme supplied. Perhaps you meant https://docker.host.internal/jobs?
[2025-03-26T16:40:27.522+0000] {logging_mixin.py:190} INFO - Task instance in failure state
[2025-03-26T16:40:27.522+0000] {logging_mixin.py:190} INFO - Task start:2025-03-26 16:40:27.321315+00:00 end:2025-03-26 16:40:27.522321+00:00 duration:0.201006
[2025-03-26T16:40:27.523+0000] {logging_mixin.py:190} INFO - Task:<Task(AirbyteTriggerSyncOperator): airbyte_metaads> dag:<DAG: trigger_airbyte_job_example> dagrun:<DagRun trigger_airbyte_job_example @ 2025-03-25 00:00:00+00:00: scheduled__2025-03-25T00:00:00+00:00, state:running, queued_at: 2025-03-26 16:40:23.047405+00:00. externally triggered: False>
[2025-03-26T16:40:27.523+0000] {logging_mixin.py:190} INFO - Failure caused by Invalid URL 'docker.host.internal/jobs': No scheme supplied. Perhaps you meant https://docker.host.internal/jobs?
[2025-03-26T16:40:27.523+0000] {taskinstance.py:1226} INFO - Marking task as FAILED. dag_id=trigger_airbyte_job_example, task_id=airbyte_metaads, run_id=scheduled__2025-03-25T00:00:00+00:00, execution_date=20250325T000000, start_date=20250326T164027, end_date=20250326T164027
[2025-03-26T16:40:27.546+0000] {taskinstance.py:341} INFO - ::group::Post task execution logs
[2025-03-26T16:40:27.546+0000] {standard_task_runner.py:124} ERROR - Failed to execute job 22 for task airbyte_metaads (Invalid URL 'docker.host.internal/jobs': No scheme supplied. Perhaps you meant https://docker.host.internal/jobs?; 348)
Traceback (most recent call last):
  File "/home/airflow/.local/lib/python3.12/site-packages/airflow/providers/airbyte/hooks/airbyte.py", line 157, in submit_sync_connection
    res = self.airbyte_api.jobs.create_job(
          ^^^^^^^^^^^^^^^^^^^^^^^^^^^^^^^^^
  File "/home/airflow/.local/lib/python3.12/site-packages/airbyte_api/jobs.py", line 100, in create_job
    raise e
  File "/home/airflow/.local/lib/python3.12/site-packages/airbyte_api/jobs.py", line 94, in create_job
    req = client.prepare_request(requests_http.Request('POST', url, params=query_params, data=data, files=form, headers=headers))
          ^^^^^^^^^^^^^^^^^^^^^^^^^^^^^^^^^^^^^^^^^^^^^^^^^^^^^^^^^^^^^^^^^^^^^^^^^^^^^^^^^^^^^^^^^^^^^^^^^^^^^^^^^^^^^^^^^^^^^^^
  File "/home/airflow/.local/lib/python3.12/site-packages/requests/sessions.py", line 484, in prepare_request
    p.prepare(
  File "/home/airflow/.local/lib/python3.12/site-packages/requests/models.py", line 367, in prepare
    self.prepare_url(url, params)
  File "/home/airflow/.local/lib/python3.12/site-packages/requests/models.py", line 438, in prepare_url
    raise MissingSchema(
requests.exceptions.MissingSchema: Invalid URL 'docker.host.internal/jobs': No scheme supplied. Perhaps you meant https://docker.host.internal/jobs?

During handling of the above exception, another exception occurred:

Traceback (most recent call last):
  File "/home/airflow/.local/lib/python3.12/site-packages/airflow/task/task_runner/standard_task_runner.py", line 117, in _start_by_fork
    ret = args.func(args, dag=self.dag)
          ^^^^^^^^^^^^^^^^^^^^^^^^^^^^^
  File "/home/airflow/.local/lib/python3.12/site-packages/airflow/cli/cli_config.py", line 49, in command
    return func(*args, **kwargs)
           ^^^^^^^^^^^^^^^^^^^^^
  File "/home/airflow/.local/lib/python3.12/site-packages/airflow/utils/cli.py", line 116, in wrapper
    return f(*args, **kwargs)
           ^^^^^^^^^^^^^^^^^^
  File "/home/airflow/.local/lib/python3.12/site-packages/airflow/cli/commands/task_command.py", line 483, in task_run
    task_return_code = _run_task_by_selected_method(args, _dag, ti)
                       ^^^^^^^^^^^^^^^^^^^^^^^^^^^^^^^^^^^^^^^^^^^^
  File "/home/airflow/.local/lib/python3.12/site-packages/airflow/cli/commands/task_command.py", line 256, in _run_task_by_selected_method
    return _run_raw_task(args, ti)
           ^^^^^^^^^^^^^^^^^^^^^^^
  File "/home/airflow/.local/lib/python3.12/site-packages/airflow/cli/commands/task_command.py", line 341, in _run_raw_task
    return ti._run_raw_task(
           ^^^^^^^^^^^^^^^^^
  File "/home/airflow/.local/lib/python3.12/site-packages/airflow/utils/session.py", line 97, in wrapper
    return func(*args, session=session, **kwargs)
           ^^^^^^^^^^^^^^^^^^^^^^^^^^^^^^^^^^^^^^
  File "/home/airflow/.local/lib/python3.12/site-packages/airflow/models/taskinstance.py", line 3006, in _run_raw_task
    return _run_raw_task(
           ^^^^^^^^^^^^^^
  File "/home/airflow/.local/lib/python3.12/site-packages/airflow/models/taskinstance.py", line 274, in _run_raw_task
    TaskInstance._execute_task_with_callbacks(
  File "/home/airflow/.local/lib/python3.12/site-packages/airflow/models/taskinstance.py", line 3161, in _execute_task_with_callbacks
    result = self._execute_task(context, task_orig)
             ^^^^^^^^^^^^^^^^^^^^^^^^^^^^^^^^^^^^^^
  File "/home/airflow/.local/lib/python3.12/site-packages/airflow/models/taskinstance.py", line 3185, in _execute_task
    return _execute_task(self, context, task_orig)
           ^^^^^^^^^^^^^^^^^^^^^^^^^^^^^^^^^^^^^^^
  File "/home/airflow/.local/lib/python3.12/site-packages/airflow/models/taskinstance.py", line 768, in _execute_task
    result = _execute_callable(context=context, **execute_callable_kwargs)
             ^^^^^^^^^^^^^^^^^^^^^^^^^^^^^^^^^^^^^^^^^^^^^^^^^^^^^^^^^^^^^
  File "/home/airflow/.local/lib/python3.12/site-packages/airflow/models/taskinstance.py", line 734, in _execute_callable
    return ExecutionCallableRunner(
           ^^^^^^^^^^^^^^^^^^^^^^^^
  File "/home/airflow/.local/lib/python3.12/site-packages/airflow/utils/operator_helpers.py", line 252, in run
    return self.func(*args, **kwargs)
           ^^^^^^^^^^^^^^^^^^^^^^^^^^
  File "/home/airflow/.local/lib/python3.12/site-packages/airflow/models/baseoperator.py", line 424, in wrapper
    return func(self, *args, **kwargs)
           ^^^^^^^^^^^^^^^^^^^^^^^^^^^
  File "/home/airflow/.local/lib/python3.12/site-packages/airflow/providers/airbyte/operators/airbyte.py", line 84, in execute
    job_object = hook.submit_sync_connection(connection_id=self.connection_id)
                 ^^^^^^^^^^^^^^^^^^^^^^^^^^^^^^^^^^^^^^^^^^^^^^^^^^^^^^^^^^^^^
  File "/home/airflow/.local/lib/python3.12/site-packages/airflow/providers/airbyte/hooks/airbyte.py", line 165, in submit_sync_connection
    raise AirflowException(e)
airflow.exceptions.AirflowException: Invalid URL 'docker.host.internal/jobs': No scheme supplied. Perhaps you meant https://docker.host.internal/jobs?
[2025-03-26T16:40:27.571+0000] {local_task_job_runner.py:266} INFO - Task exited with return code 1
[2025-03-26T16:40:27.589+0000] {taskinstance.py:3901} INFO - 0 downstream tasks scheduled from follow-on schedule check
[2025-03-26T16:40:27.590+0000] {local_task_job_runner.py:245} INFO - ::endgroup::
[2025-03-26T16:59:39.833+0000] {local_task_job_runner.py:123} INFO - ::group::Pre task execution logs
[2025-03-26T16:59:39.850+0000] {taskinstance.py:2614} INFO - Dependencies all met for dep_context=non-requeueable deps ti=<TaskInstance: trigger_airbyte_job_example.airbyte_metaads scheduled__2025-03-25T00:00:00+00:00 [queued]>
[2025-03-26T16:59:39.858+0000] {taskinstance.py:2614} INFO - Dependencies all met for dep_context=requeueable deps ti=<TaskInstance: trigger_airbyte_job_example.airbyte_metaads scheduled__2025-03-25T00:00:00+00:00 [queued]>
[2025-03-26T16:59:39.858+0000] {taskinstance.py:2867} INFO - Starting attempt 1 of 1
[2025-03-26T16:59:39.871+0000] {taskinstance.py:2890} INFO - Executing <Task(AirbyteTriggerSyncOperator): airbyte_metaads> on 2025-03-25 00:00:00+00:00
[2025-03-26T16:59:39.887+0000] {warnings.py:112} WARNING - /home/***/.local/lib/python3.12/site-packages/***/task/task_runner/standard_task_runner.py:70: DeprecationWarning: This process (pid=1173) is multi-threaded, use of fork() may lead to deadlocks in the child.
  pid = os.fork()

[2025-03-26T16:59:39.888+0000] {standard_task_runner.py:72} INFO - Started process 1176 to run task
[2025-03-26T16:59:39.888+0000] {standard_task_runner.py:104} INFO - Running: ['***', 'tasks', 'run', 'trigger_airbyte_job_example', 'airbyte_metaads', 'scheduled__2025-03-25T00:00:00+00:00', '--job-id', '24', '--raw', '--subdir', 'DAGS_FOLDER/meta_ads_dag.py', '--cfg-path', '/tmp/tmp5pxtp67n']
[2025-03-26T16:59:39.889+0000] {standard_task_runner.py:105} INFO - Job 24: Subtask airbyte_metaads
[2025-03-26T16:59:39.936+0000] {task_command.py:467} INFO - Running <TaskInstance: trigger_airbyte_job_example.airbyte_metaads scheduled__2025-03-25T00:00:00+00:00 [running]> on host e3e3ae5ea89f
[2025-03-26T16:59:40.007+0000] {taskinstance.py:3134} INFO - Exporting env vars: AIRFLOW_CTX_DAG_OWNER='***' AIRFLOW_CTX_DAG_ID='trigger_airbyte_job_example' AIRFLOW_CTX_TASK_ID='airbyte_metaads' AIRFLOW_CTX_EXECUTION_DATE='2025-03-25T00:00:00+00:00' AIRFLOW_CTX_TRY_NUMBER='1' AIRFLOW_CTX_DAG_RUN_ID='scheduled__2025-03-25T00:00:00+00:00'
[2025-03-26T16:59:40.010+0000] {logging_mixin.py:190} INFO - Task instance is in running state
[2025-03-26T16:59:40.010+0000] {logging_mixin.py:190} INFO -  Previous state of the Task instance: queued
[2025-03-26T16:59:40.010+0000] {logging_mixin.py:190} INFO - Current task name:airbyte_metaads state:running start_date:2025-03-26 16:59:39.850791+00:00
[2025-03-26T16:59:40.010+0000] {logging_mixin.py:190} INFO - Dag name:trigger_airbyte_job_example and current dag run status:running
[2025-03-26T16:59:40.010+0000] {taskinstance.py:732} INFO - ::endgroup::
[2025-03-26T16:59:40.019+0000] {base.py:84} INFO - Retrieving connection 'airbyte_conn'
[2025-03-26T16:59:40.035+0000] {taskinstance.py:3313} ERROR - Task failed with exception
Traceback (most recent call last):
  File "/home/airflow/.local/lib/python3.12/site-packages/airflow/providers/airbyte/hooks/airbyte.py", line 157, in submit_sync_connection
    res = self.airbyte_api.jobs.create_job(
          ^^^^^^^^^^^^^^^^^^^^^^^^^^^^^^^^^
  File "/home/airflow/.local/lib/python3.12/site-packages/airbyte_api/jobs.py", line 100, in create_job
    raise e
  File "/home/airflow/.local/lib/python3.12/site-packages/airbyte_api/jobs.py", line 94, in create_job
    req = client.prepare_request(requests_http.Request('POST', url, params=query_params, data=data, files=form, headers=headers))
          ^^^^^^^^^^^^^^^^^^^^^^^^^^^^^^^^^^^^^^^^^^^^^^^^^^^^^^^^^^^^^^^^^^^^^^^^^^^^^^^^^^^^^^^^^^^^^^^^^^^^^^^^^^^^^^^^^^^^^^^
  File "/home/airflow/.local/lib/python3.12/site-packages/requests/sessions.py", line 484, in prepare_request
    p.prepare(
  File "/home/airflow/.local/lib/python3.12/site-packages/requests/models.py", line 367, in prepare
    self.prepare_url(url, params)
  File "/home/airflow/.local/lib/python3.12/site-packages/requests/models.py", line 438, in prepare_url
    raise MissingSchema(
requests.exceptions.MissingSchema: Invalid URL 'localhost/jobs': No scheme supplied. Perhaps you meant https://localhost/jobs?

During handling of the above exception, another exception occurred:

Traceback (most recent call last):
  File "/home/airflow/.local/lib/python3.12/site-packages/airflow/models/taskinstance.py", line 768, in _execute_task
    result = _execute_callable(context=context, **execute_callable_kwargs)
             ^^^^^^^^^^^^^^^^^^^^^^^^^^^^^^^^^^^^^^^^^^^^^^^^^^^^^^^^^^^^^
  File "/home/airflow/.local/lib/python3.12/site-packages/airflow/models/taskinstance.py", line 734, in _execute_callable
    return ExecutionCallableRunner(
           ^^^^^^^^^^^^^^^^^^^^^^^^
  File "/home/airflow/.local/lib/python3.12/site-packages/airflow/utils/operator_helpers.py", line 252, in run
    return self.func(*args, **kwargs)
           ^^^^^^^^^^^^^^^^^^^^^^^^^^
  File "/home/airflow/.local/lib/python3.12/site-packages/airflow/models/baseoperator.py", line 424, in wrapper
    return func(self, *args, **kwargs)
           ^^^^^^^^^^^^^^^^^^^^^^^^^^^
  File "/home/airflow/.local/lib/python3.12/site-packages/airflow/providers/airbyte/operators/airbyte.py", line 84, in execute
    job_object = hook.submit_sync_connection(connection_id=self.connection_id)
                 ^^^^^^^^^^^^^^^^^^^^^^^^^^^^^^^^^^^^^^^^^^^^^^^^^^^^^^^^^^^^^
  File "/home/airflow/.local/lib/python3.12/site-packages/airflow/providers/airbyte/hooks/airbyte.py", line 165, in submit_sync_connection
    raise AirflowException(e)
airflow.exceptions.AirflowException: Invalid URL 'localhost/jobs': No scheme supplied. Perhaps you meant https://localhost/jobs?
[2025-03-26T16:59:40.039+0000] {logging_mixin.py:190} INFO - Task instance in failure state
[2025-03-26T16:59:40.039+0000] {logging_mixin.py:190} INFO - Task start:2025-03-26 16:59:39.850791+00:00 end:2025-03-26 16:59:40.039050+00:00 duration:0.188259
[2025-03-26T16:59:40.039+0000] {logging_mixin.py:190} INFO - Task:<Task(AirbyteTriggerSyncOperator): airbyte_metaads> dag:<DAG: trigger_airbyte_job_example> dagrun:<DagRun trigger_airbyte_job_example @ 2025-03-25 00:00:00+00:00: scheduled__2025-03-25T00:00:00+00:00, state:running, queued_at: 2025-03-26 16:59:37.611450+00:00. externally triggered: False>
[2025-03-26T16:59:40.040+0000] {logging_mixin.py:190} INFO - Failure caused by Invalid URL 'localhost/jobs': No scheme supplied. Perhaps you meant https://localhost/jobs?
[2025-03-26T16:59:40.040+0000] {taskinstance.py:1226} INFO - Marking task as FAILED. dag_id=trigger_airbyte_job_example, task_id=airbyte_metaads, run_id=scheduled__2025-03-25T00:00:00+00:00, execution_date=20250325T000000, start_date=20250326T165939, end_date=20250326T165940
[2025-03-26T16:59:40.066+0000] {taskinstance.py:341} INFO - ::group::Post task execution logs
[2025-03-26T16:59:40.066+0000] {standard_task_runner.py:124} ERROR - Failed to execute job 24 for task airbyte_metaads (Invalid URL 'localhost/jobs': No scheme supplied. Perhaps you meant https://localhost/jobs?; 1176)
Traceback (most recent call last):
  File "/home/airflow/.local/lib/python3.12/site-packages/airflow/providers/airbyte/hooks/airbyte.py", line 157, in submit_sync_connection
    res = self.airbyte_api.jobs.create_job(
          ^^^^^^^^^^^^^^^^^^^^^^^^^^^^^^^^^
  File "/home/airflow/.local/lib/python3.12/site-packages/airbyte_api/jobs.py", line 100, in create_job
    raise e
  File "/home/airflow/.local/lib/python3.12/site-packages/airbyte_api/jobs.py", line 94, in create_job
    req = client.prepare_request(requests_http.Request('POST', url, params=query_params, data=data, files=form, headers=headers))
          ^^^^^^^^^^^^^^^^^^^^^^^^^^^^^^^^^^^^^^^^^^^^^^^^^^^^^^^^^^^^^^^^^^^^^^^^^^^^^^^^^^^^^^^^^^^^^^^^^^^^^^^^^^^^^^^^^^^^^^^
  File "/home/airflow/.local/lib/python3.12/site-packages/requests/sessions.py", line 484, in prepare_request
    p.prepare(
  File "/home/airflow/.local/lib/python3.12/site-packages/requests/models.py", line 367, in prepare
    self.prepare_url(url, params)
  File "/home/airflow/.local/lib/python3.12/site-packages/requests/models.py", line 438, in prepare_url
    raise MissingSchema(
requests.exceptions.MissingSchema: Invalid URL 'localhost/jobs': No scheme supplied. Perhaps you meant https://localhost/jobs?

During handling of the above exception, another exception occurred:

Traceback (most recent call last):
  File "/home/airflow/.local/lib/python3.12/site-packages/airflow/task/task_runner/standard_task_runner.py", line 117, in _start_by_fork
    ret = args.func(args, dag=self.dag)
          ^^^^^^^^^^^^^^^^^^^^^^^^^^^^^
  File "/home/airflow/.local/lib/python3.12/site-packages/airflow/cli/cli_config.py", line 49, in command
    return func(*args, **kwargs)
           ^^^^^^^^^^^^^^^^^^^^^
  File "/home/airflow/.local/lib/python3.12/site-packages/airflow/utils/cli.py", line 116, in wrapper
    return f(*args, **kwargs)
           ^^^^^^^^^^^^^^^^^^
  File "/home/airflow/.local/lib/python3.12/site-packages/airflow/cli/commands/task_command.py", line 483, in task_run
    task_return_code = _run_task_by_selected_method(args, _dag, ti)
                       ^^^^^^^^^^^^^^^^^^^^^^^^^^^^^^^^^^^^^^^^^^^^
  File "/home/airflow/.local/lib/python3.12/site-packages/airflow/cli/commands/task_command.py", line 256, in _run_task_by_selected_method
    return _run_raw_task(args, ti)
           ^^^^^^^^^^^^^^^^^^^^^^^
  File "/home/airflow/.local/lib/python3.12/site-packages/airflow/cli/commands/task_command.py", line 341, in _run_raw_task
    return ti._run_raw_task(
           ^^^^^^^^^^^^^^^^^
  File "/home/airflow/.local/lib/python3.12/site-packages/airflow/utils/session.py", line 97, in wrapper
    return func(*args, session=session, **kwargs)
           ^^^^^^^^^^^^^^^^^^^^^^^^^^^^^^^^^^^^^^
  File "/home/airflow/.local/lib/python3.12/site-packages/airflow/models/taskinstance.py", line 3006, in _run_raw_task
    return _run_raw_task(
           ^^^^^^^^^^^^^^
  File "/home/airflow/.local/lib/python3.12/site-packages/airflow/models/taskinstance.py", line 274, in _run_raw_task
    TaskInstance._execute_task_with_callbacks(
  File "/home/airflow/.local/lib/python3.12/site-packages/airflow/models/taskinstance.py", line 3161, in _execute_task_with_callbacks
    result = self._execute_task(context, task_orig)
             ^^^^^^^^^^^^^^^^^^^^^^^^^^^^^^^^^^^^^^
  File "/home/airflow/.local/lib/python3.12/site-packages/airflow/models/taskinstance.py", line 3185, in _execute_task
    return _execute_task(self, context, task_orig)
           ^^^^^^^^^^^^^^^^^^^^^^^^^^^^^^^^^^^^^^^
  File "/home/airflow/.local/lib/python3.12/site-packages/airflow/models/taskinstance.py", line 768, in _execute_task
    result = _execute_callable(context=context, **execute_callable_kwargs)
             ^^^^^^^^^^^^^^^^^^^^^^^^^^^^^^^^^^^^^^^^^^^^^^^^^^^^^^^^^^^^^
  File "/home/airflow/.local/lib/python3.12/site-packages/airflow/models/taskinstance.py", line 734, in _execute_callable
    return ExecutionCallableRunner(
           ^^^^^^^^^^^^^^^^^^^^^^^^
  File "/home/airflow/.local/lib/python3.12/site-packages/airflow/utils/operator_helpers.py", line 252, in run
    return self.func(*args, **kwargs)
           ^^^^^^^^^^^^^^^^^^^^^^^^^^
  File "/home/airflow/.local/lib/python3.12/site-packages/airflow/models/baseoperator.py", line 424, in wrapper
    return func(self, *args, **kwargs)
           ^^^^^^^^^^^^^^^^^^^^^^^^^^^
  File "/home/airflow/.local/lib/python3.12/site-packages/airflow/providers/airbyte/operators/airbyte.py", line 84, in execute
    job_object = hook.submit_sync_connection(connection_id=self.connection_id)
                 ^^^^^^^^^^^^^^^^^^^^^^^^^^^^^^^^^^^^^^^^^^^^^^^^^^^^^^^^^^^^^
  File "/home/airflow/.local/lib/python3.12/site-packages/airflow/providers/airbyte/hooks/airbyte.py", line 165, in submit_sync_connection
    raise AirflowException(e)
airflow.exceptions.AirflowException: Invalid URL 'localhost/jobs': No scheme supplied. Perhaps you meant https://localhost/jobs?
[2025-03-26T16:59:40.102+0000] {local_task_job_runner.py:266} INFO - Task exited with return code 1
[2025-03-26T16:59:40.124+0000] {taskinstance.py:3901} INFO - 0 downstream tasks scheduled from follow-on schedule check
[2025-03-26T16:59:40.125+0000] {local_task_job_runner.py:245} INFO - ::endgroup::
