[2025-04-10T17:28:34.632+0000] {local_task_job_runner.py:123} INFO - ::group::Pre task execution logs
[2025-04-10T17:28:34.648+0000] {taskinstance.py:2614} INFO - Dependencies all met for dep_context=non-requeueable deps ti=<TaskInstance: meta_ads_elt_pipeline.airbyte_sync.trigger_connection_sync scheduled__2025-04-09T00:00:00+00:00 [queued]>
[2025-04-10T17:28:34.656+0000] {taskinstance.py:2614} INFO - Dependencies all met for dep_context=requeueable deps ti=<TaskInstance: meta_ads_elt_pipeline.airbyte_sync.trigger_connection_sync scheduled__2025-04-09T00:00:00+00:00 [queued]>
[2025-04-10T17:28:34.656+0000] {taskinstance.py:2867} INFO - Starting attempt 1 of 3
[2025-04-10T17:28:34.669+0000] {taskinstance.py:2890} INFO - Executing <Task(HttpOperator): airbyte_sync.trigger_connection_sync> on 2025-04-09 00:00:00+00:00
[2025-04-10T17:28:34.684+0000] {warnings.py:112} WARNING - /home/***/.local/lib/python3.12/site-packages/***/task/task_runner/standard_task_runner.py:70: DeprecationWarning: This process (pid=127) is multi-threaded, use of fork() may lead to deadlocks in the child.
  pid = os.fork()

[2025-04-10T17:28:34.685+0000] {standard_task_runner.py:72} INFO - Started process 133 to run task
[2025-04-10T17:28:34.686+0000] {standard_task_runner.py:104} INFO - Running: ['***', 'tasks', 'run', 'meta_ads_elt_pipeline', 'airbyte_sync.trigger_connection_sync', 'scheduled__2025-04-09T00:00:00+00:00', '--job-id', '335', '--raw', '--subdir', 'DAGS_FOLDER/meta_ads_elt_pipeline.py', '--cfg-path', '/tmp/tmp8z0vzg97']
[2025-04-10T17:28:34.687+0000] {standard_task_runner.py:105} INFO - Job 335: Subtask airbyte_sync.trigger_connection_sync
[2025-04-10T17:28:34.729+0000] {task_command.py:467} INFO - Running <TaskInstance: meta_ads_elt_pipeline.airbyte_sync.trigger_connection_sync scheduled__2025-04-09T00:00:00+00:00 [running]> on host ffa99f2ae5fe
[2025-04-10T17:28:34.808+0000] {taskinstance.py:3134} INFO - Exporting env vars: AIRFLOW_CTX_DAG_OWNER='admin' AIRFLOW_CTX_DAG_ID='meta_ads_elt_pipeline' AIRFLOW_CTX_TASK_ID='airbyte_sync.trigger_connection_sync' AIRFLOW_CTX_EXECUTION_DATE='2025-04-09T00:00:00+00:00' AIRFLOW_CTX_TRY_NUMBER='1' AIRFLOW_CTX_DAG_RUN_ID='scheduled__2025-04-09T00:00:00+00:00'
[2025-04-10T17:28:34.809+0000] {logging_mixin.py:190} INFO - Task instance is in running state
[2025-04-10T17:28:34.810+0000] {logging_mixin.py:190} INFO -  Previous state of the Task instance: queued
[2025-04-10T17:28:34.810+0000] {logging_mixin.py:190} INFO - Current task name:airbyte_sync.trigger_connection_sync state:running start_date:2025-04-10 17:28:34.648520+00:00
[2025-04-10T17:28:34.810+0000] {logging_mixin.py:190} INFO - Dag name:meta_ads_elt_pipeline and current dag run status:running
[2025-04-10T17:28:34.810+0000] {taskinstance.py:732} INFO - ::endgroup::
[2025-04-10T17:28:34.811+0000] {http.py:180} INFO - Calling HTTP method
[2025-04-10T17:28:34.818+0000] {base.py:84} INFO - Retrieving connection 'airbyte'
[2025-04-10T17:28:34.827+0000] {base.py:84} INFO - Retrieving connection 'airbyte'
[2025-04-10T17:28:34.831+0000] {http.py:322} WARNING - ('Connection aborted.', ConnectionResetError(104, 'Connection reset by peer')) Tenacity will retry to execute the operation
[2025-04-10T17:28:34.832+0000] {taskinstance.py:3313} ERROR - Task failed with exception
Traceback (most recent call last):
  File "/home/airflow/.local/lib/python3.12/site-packages/urllib3/connectionpool.py", line 787, in urlopen
    response = self._make_request(
               ^^^^^^^^^^^^^^^^^^^
  File "/home/airflow/.local/lib/python3.12/site-packages/urllib3/connectionpool.py", line 534, in _make_request
    response = conn.getresponse()
               ^^^^^^^^^^^^^^^^^^
  File "/home/airflow/.local/lib/python3.12/site-packages/urllib3/connection.py", line 516, in getresponse
    httplib_response = super().getresponse()
                       ^^^^^^^^^^^^^^^^^^^^^
  File "/usr/local/lib/python3.12/http/client.py", line 1430, in getresponse
    response.begin()
  File "/usr/local/lib/python3.12/http/client.py", line 331, in begin
    version, status, reason = self._read_status()
                              ^^^^^^^^^^^^^^^^^^^
  File "/usr/local/lib/python3.12/http/client.py", line 292, in _read_status
    line = str(self.fp.readline(_MAXLINE + 1), "iso-8859-1")
               ^^^^^^^^^^^^^^^^^^^^^^^^^^^^^^
  File "/usr/local/lib/python3.12/socket.py", line 720, in readinto
    return self._sock.recv_into(b)
           ^^^^^^^^^^^^^^^^^^^^^^^
ConnectionResetError: [Errno 104] Connection reset by peer

During handling of the above exception, another exception occurred:

Traceback (most recent call last):
  File "/home/airflow/.local/lib/python3.12/site-packages/requests/adapters.py", line 667, in send
    resp = conn.urlopen(
           ^^^^^^^^^^^^^
  File "/home/airflow/.local/lib/python3.12/site-packages/urllib3/connectionpool.py", line 841, in urlopen
    retries = retries.increment(
              ^^^^^^^^^^^^^^^^^^
  File "/home/airflow/.local/lib/python3.12/site-packages/urllib3/util/retry.py", line 474, in increment
    raise reraise(type(error), error, _stacktrace)
          ^^^^^^^^^^^^^^^^^^^^^^^^^^^^^^^^^^^^^^^^
  File "/home/airflow/.local/lib/python3.12/site-packages/urllib3/util/util.py", line 38, in reraise
    raise value.with_traceback(tb)
  File "/home/airflow/.local/lib/python3.12/site-packages/urllib3/connectionpool.py", line 787, in urlopen
    response = self._make_request(
               ^^^^^^^^^^^^^^^^^^^
  File "/home/airflow/.local/lib/python3.12/site-packages/urllib3/connectionpool.py", line 534, in _make_request
    response = conn.getresponse()
               ^^^^^^^^^^^^^^^^^^
  File "/home/airflow/.local/lib/python3.12/site-packages/urllib3/connection.py", line 516, in getresponse
    httplib_response = super().getresponse()
                       ^^^^^^^^^^^^^^^^^^^^^
  File "/usr/local/lib/python3.12/http/client.py", line 1430, in getresponse
    response.begin()
  File "/usr/local/lib/python3.12/http/client.py", line 331, in begin
    version, status, reason = self._read_status()
                              ^^^^^^^^^^^^^^^^^^^
  File "/usr/local/lib/python3.12/http/client.py", line 292, in _read_status
    line = str(self.fp.readline(_MAXLINE + 1), "iso-8859-1")
               ^^^^^^^^^^^^^^^^^^^^^^^^^^^^^^
  File "/usr/local/lib/python3.12/socket.py", line 720, in readinto
    return self._sock.recv_into(b)
           ^^^^^^^^^^^^^^^^^^^^^^^
urllib3.exceptions.ProtocolError: ('Connection aborted.', ConnectionResetError(104, 'Connection reset by peer'))

During handling of the above exception, another exception occurred:

Traceback (most recent call last):
  File "/home/airflow/.local/lib/python3.12/site-packages/airflow/models/taskinstance.py", line 768, in _execute_task
    result = _execute_callable(context=context, **execute_callable_kwargs)
             ^^^^^^^^^^^^^^^^^^^^^^^^^^^^^^^^^^^^^^^^^^^^^^^^^^^^^^^^^^^^^
  File "/home/airflow/.local/lib/python3.12/site-packages/airflow/models/taskinstance.py", line 734, in _execute_callable
    return ExecutionCallableRunner(
           ^^^^^^^^^^^^^^^^^^^^^^^^
  File "/home/airflow/.local/lib/python3.12/site-packages/airflow/utils/operator_helpers.py", line 252, in run
    return self.func(*args, **kwargs)
           ^^^^^^^^^^^^^^^^^^^^^^^^^^
  File "/home/airflow/.local/lib/python3.12/site-packages/airflow/models/baseoperator.py", line 424, in wrapper
    return func(self, *args, **kwargs)
           ^^^^^^^^^^^^^^^^^^^^^^^^^^^
  File "/home/airflow/.local/lib/python3.12/site-packages/airflow/providers/http/operators/http.py", line 177, in execute
    return self.execute_sync(context=context)
           ^^^^^^^^^^^^^^^^^^^^^^^^^^^^^^^^^^
  File "/home/airflow/.local/lib/python3.12/site-packages/airflow/providers/http/operators/http.py", line 191, in execute_sync
    response = self.hook.run(
               ^^^^^^^^^^^^^^
  File "/home/airflow/.local/lib/python3.12/site-packages/airflow/providers/http/hooks/http.py", line 265, in run
    return self.run_and_check(session, prepped_request, extra_options)
           ^^^^^^^^^^^^^^^^^^^^^^^^^^^^^^^^^^^^^^^^^^^^^^^^^^^^^^^^^^^
  File "/home/airflow/.local/lib/python3.12/site-packages/airflow/providers/http/hooks/http.py", line 323, in run_and_check
    raise ex
  File "/home/airflow/.local/lib/python3.12/site-packages/airflow/providers/http/hooks/http.py", line 315, in run_and_check
    response = session.send(prepped_request, **send_kwargs)
               ^^^^^^^^^^^^^^^^^^^^^^^^^^^^^^^^^^^^^^^^^^^^
  File "/home/airflow/.local/lib/python3.12/site-packages/requests/sessions.py", line 703, in send
    r = adapter.send(request, **kwargs)
        ^^^^^^^^^^^^^^^^^^^^^^^^^^^^^^^
  File "/home/airflow/.local/lib/python3.12/site-packages/requests/adapters.py", line 682, in send
    raise ConnectionError(err, request=request)
requests.exceptions.ConnectionError: ('Connection aborted.', ConnectionResetError(104, 'Connection reset by peer'))
[2025-04-10T17:28:34.847+0000] {logging_mixin.py:190} INFO - Task instance in failure state
[2025-04-10T17:28:34.847+0000] {logging_mixin.py:190} INFO - Task start:2025-04-10 17:28:34.648520+00:00 end:2025-04-10 17:28:34.846546+00:00 duration:0.198026
[2025-04-10T17:28:34.847+0000] {logging_mixin.py:190} INFO - Task:<Task(HttpOperator): airbyte_sync.trigger_connection_sync> dag:<DAG: meta_ads_elt_pipeline> dagrun:<DagRun meta_ads_elt_pipeline @ 2025-04-09 00:00:00+00:00: scheduled__2025-04-09T00:00:00+00:00, state:running, queued_at: 2025-04-10 17:28:27.279620+00:00. externally triggered: False>
[2025-04-10T17:28:34.847+0000] {logging_mixin.py:190} INFO - Failure caused by ('Connection aborted.', ConnectionResetError(104, 'Connection reset by peer'))
[2025-04-10T17:28:34.847+0000] {taskinstance.py:1226} INFO - Marking task as UP_FOR_RETRY. dag_id=meta_ads_elt_pipeline, task_id=airbyte_sync.trigger_connection_sync, run_id=scheduled__2025-04-09T00:00:00+00:00, execution_date=20250409T000000, start_date=20250410T172834, end_date=20250410T172834
[2025-04-10T17:28:34.871+0000] {taskinstance.py:341} INFO - ::group::Post task execution logs
[2025-04-10T17:28:34.871+0000] {standard_task_runner.py:124} ERROR - Failed to execute job 335 for task airbyte_sync.trigger_connection_sync (('Connection aborted.', ConnectionResetError(104, 'Connection reset by peer')); 133)
Traceback (most recent call last):
  File "/home/airflow/.local/lib/python3.12/site-packages/urllib3/connectionpool.py", line 787, in urlopen
    response = self._make_request(
               ^^^^^^^^^^^^^^^^^^^
  File "/home/airflow/.local/lib/python3.12/site-packages/urllib3/connectionpool.py", line 534, in _make_request
    response = conn.getresponse()
               ^^^^^^^^^^^^^^^^^^
  File "/home/airflow/.local/lib/python3.12/site-packages/urllib3/connection.py", line 516, in getresponse
    httplib_response = super().getresponse()
                       ^^^^^^^^^^^^^^^^^^^^^
  File "/usr/local/lib/python3.12/http/client.py", line 1430, in getresponse
    response.begin()
  File "/usr/local/lib/python3.12/http/client.py", line 331, in begin
    version, status, reason = self._read_status()
                              ^^^^^^^^^^^^^^^^^^^
  File "/usr/local/lib/python3.12/http/client.py", line 292, in _read_status
    line = str(self.fp.readline(_MAXLINE + 1), "iso-8859-1")
               ^^^^^^^^^^^^^^^^^^^^^^^^^^^^^^
  File "/usr/local/lib/python3.12/socket.py", line 720, in readinto
    return self._sock.recv_into(b)
           ^^^^^^^^^^^^^^^^^^^^^^^
ConnectionResetError: [Errno 104] Connection reset by peer

During handling of the above exception, another exception occurred:

Traceback (most recent call last):
  File "/home/airflow/.local/lib/python3.12/site-packages/requests/adapters.py", line 667, in send
    resp = conn.urlopen(
           ^^^^^^^^^^^^^
  File "/home/airflow/.local/lib/python3.12/site-packages/urllib3/connectionpool.py", line 841, in urlopen
    retries = retries.increment(
              ^^^^^^^^^^^^^^^^^^
  File "/home/airflow/.local/lib/python3.12/site-packages/urllib3/util/retry.py", line 474, in increment
    raise reraise(type(error), error, _stacktrace)
          ^^^^^^^^^^^^^^^^^^^^^^^^^^^^^^^^^^^^^^^^
  File "/home/airflow/.local/lib/python3.12/site-packages/urllib3/util/util.py", line 38, in reraise
    raise value.with_traceback(tb)
  File "/home/airflow/.local/lib/python3.12/site-packages/urllib3/connectionpool.py", line 787, in urlopen
    response = self._make_request(
               ^^^^^^^^^^^^^^^^^^^
  File "/home/airflow/.local/lib/python3.12/site-packages/urllib3/connectionpool.py", line 534, in _make_request
    response = conn.getresponse()
               ^^^^^^^^^^^^^^^^^^
  File "/home/airflow/.local/lib/python3.12/site-packages/urllib3/connection.py", line 516, in getresponse
    httplib_response = super().getresponse()
                       ^^^^^^^^^^^^^^^^^^^^^
  File "/usr/local/lib/python3.12/http/client.py", line 1430, in getresponse
    response.begin()
  File "/usr/local/lib/python3.12/http/client.py", line 331, in begin
    version, status, reason = self._read_status()
                              ^^^^^^^^^^^^^^^^^^^
  File "/usr/local/lib/python3.12/http/client.py", line 292, in _read_status
    line = str(self.fp.readline(_MAXLINE + 1), "iso-8859-1")
               ^^^^^^^^^^^^^^^^^^^^^^^^^^^^^^
  File "/usr/local/lib/python3.12/socket.py", line 720, in readinto
    return self._sock.recv_into(b)
           ^^^^^^^^^^^^^^^^^^^^^^^
urllib3.exceptions.ProtocolError: ('Connection aborted.', ConnectionResetError(104, 'Connection reset by peer'))

During handling of the above exception, another exception occurred:

Traceback (most recent call last):
  File "/home/airflow/.local/lib/python3.12/site-packages/airflow/task/task_runner/standard_task_runner.py", line 117, in _start_by_fork
    ret = args.func(args, dag=self.dag)
          ^^^^^^^^^^^^^^^^^^^^^^^^^^^^^
  File "/home/airflow/.local/lib/python3.12/site-packages/airflow/cli/cli_config.py", line 49, in command
    return func(*args, **kwargs)
           ^^^^^^^^^^^^^^^^^^^^^
  File "/home/airflow/.local/lib/python3.12/site-packages/airflow/utils/cli.py", line 116, in wrapper
    return f(*args, **kwargs)
           ^^^^^^^^^^^^^^^^^^
  File "/home/airflow/.local/lib/python3.12/site-packages/airflow/cli/commands/task_command.py", line 483, in task_run
    task_return_code = _run_task_by_selected_method(args, _dag, ti)
                       ^^^^^^^^^^^^^^^^^^^^^^^^^^^^^^^^^^^^^^^^^^^^
  File "/home/airflow/.local/lib/python3.12/site-packages/airflow/cli/commands/task_command.py", line 256, in _run_task_by_selected_method
    return _run_raw_task(args, ti)
           ^^^^^^^^^^^^^^^^^^^^^^^
  File "/home/airflow/.local/lib/python3.12/site-packages/airflow/cli/commands/task_command.py", line 341, in _run_raw_task
    return ti._run_raw_task(
           ^^^^^^^^^^^^^^^^^
  File "/home/airflow/.local/lib/python3.12/site-packages/airflow/utils/session.py", line 97, in wrapper
    return func(*args, session=session, **kwargs)
           ^^^^^^^^^^^^^^^^^^^^^^^^^^^^^^^^^^^^^^
  File "/home/airflow/.local/lib/python3.12/site-packages/airflow/models/taskinstance.py", line 3006, in _run_raw_task
    return _run_raw_task(
           ^^^^^^^^^^^^^^
  File "/home/airflow/.local/lib/python3.12/site-packages/airflow/models/taskinstance.py", line 274, in _run_raw_task
    TaskInstance._execute_task_with_callbacks(
  File "/home/airflow/.local/lib/python3.12/site-packages/airflow/models/taskinstance.py", line 3161, in _execute_task_with_callbacks
    result = self._execute_task(context, task_orig)
             ^^^^^^^^^^^^^^^^^^^^^^^^^^^^^^^^^^^^^^
  File "/home/airflow/.local/lib/python3.12/site-packages/airflow/models/taskinstance.py", line 3185, in _execute_task
    return _execute_task(self, context, task_orig)
           ^^^^^^^^^^^^^^^^^^^^^^^^^^^^^^^^^^^^^^^
  File "/home/airflow/.local/lib/python3.12/site-packages/airflow/models/taskinstance.py", line 768, in _execute_task
    result = _execute_callable(context=context, **execute_callable_kwargs)
             ^^^^^^^^^^^^^^^^^^^^^^^^^^^^^^^^^^^^^^^^^^^^^^^^^^^^^^^^^^^^^
  File "/home/airflow/.local/lib/python3.12/site-packages/airflow/models/taskinstance.py", line 734, in _execute_callable
    return ExecutionCallableRunner(
           ^^^^^^^^^^^^^^^^^^^^^^^^
  File "/home/airflow/.local/lib/python3.12/site-packages/airflow/utils/operator_helpers.py", line 252, in run
    return self.func(*args, **kwargs)
           ^^^^^^^^^^^^^^^^^^^^^^^^^^
  File "/home/airflow/.local/lib/python3.12/site-packages/airflow/models/baseoperator.py", line 424, in wrapper
    return func(self, *args, **kwargs)
           ^^^^^^^^^^^^^^^^^^^^^^^^^^^
  File "/home/airflow/.local/lib/python3.12/site-packages/airflow/providers/http/operators/http.py", line 177, in execute
    return self.execute_sync(context=context)
           ^^^^^^^^^^^^^^^^^^^^^^^^^^^^^^^^^^
  File "/home/airflow/.local/lib/python3.12/site-packages/airflow/providers/http/operators/http.py", line 191, in execute_sync
    response = self.hook.run(
               ^^^^^^^^^^^^^^
  File "/home/airflow/.local/lib/python3.12/site-packages/airflow/providers/http/hooks/http.py", line 265, in run
    return self.run_and_check(session, prepped_request, extra_options)
           ^^^^^^^^^^^^^^^^^^^^^^^^^^^^^^^^^^^^^^^^^^^^^^^^^^^^^^^^^^^
  File "/home/airflow/.local/lib/python3.12/site-packages/airflow/providers/http/hooks/http.py", line 323, in run_and_check
    raise ex
  File "/home/airflow/.local/lib/python3.12/site-packages/airflow/providers/http/hooks/http.py", line 315, in run_and_check
    response = session.send(prepped_request, **send_kwargs)
               ^^^^^^^^^^^^^^^^^^^^^^^^^^^^^^^^^^^^^^^^^^^^
  File "/home/airflow/.local/lib/python3.12/site-packages/requests/sessions.py", line 703, in send
    r = adapter.send(request, **kwargs)
        ^^^^^^^^^^^^^^^^^^^^^^^^^^^^^^^
  File "/home/airflow/.local/lib/python3.12/site-packages/requests/adapters.py", line 682, in send
    raise ConnectionError(err, request=request)
requests.exceptions.ConnectionError: ('Connection aborted.', ConnectionResetError(104, 'Connection reset by peer'))
[2025-04-10T17:28:34.900+0000] {local_task_job_runner.py:266} INFO - Task exited with return code 1
[2025-04-10T17:28:34.925+0000] {taskinstance.py:3901} INFO - 0 downstream tasks scheduled from follow-on schedule check
[2025-04-10T17:28:34.926+0000] {local_task_job_runner.py:245} INFO - ::endgroup::
[2025-04-10T22:13:10.797+0000] {local_task_job_runner.py:123} INFO - ::group::Pre task execution logs
[2025-04-10T22:13:10.814+0000] {taskinstance.py:2614} INFO - Dependencies all met for dep_context=non-requeueable deps ti=<TaskInstance: meta_ads_elt_pipeline.airbyte_sync.trigger_connection_sync scheduled__2025-04-09T00:00:00+00:00 [queued]>
[2025-04-10T22:13:10.819+0000] {taskinstance.py:2614} INFO - Dependencies all met for dep_context=requeueable deps ti=<TaskInstance: meta_ads_elt_pipeline.airbyte_sync.trigger_connection_sync scheduled__2025-04-09T00:00:00+00:00 [queued]>
[2025-04-10T22:13:10.819+0000] {taskinstance.py:2867} INFO - Starting attempt 1 of 3
[2025-04-10T22:13:10.828+0000] {taskinstance.py:2890} INFO - Executing <Task(HttpOperator): airbyte_sync.trigger_connection_sync> on 2025-04-09 00:00:00+00:00
[2025-04-10T22:13:10.840+0000] {warnings.py:112} WARNING - /home/***/.local/lib/python3.12/site-packages/***/task/task_runner/standard_task_runner.py:70: DeprecationWarning: This process (pid=1366) is multi-threaded, use of fork() may lead to deadlocks in the child.
  pid = os.fork()

[2025-04-10T22:13:10.842+0000] {standard_task_runner.py:72} INFO - Started process 1372 to run task
[2025-04-10T22:13:10.844+0000] {standard_task_runner.py:104} INFO - Running: ['***', 'tasks', 'run', 'meta_ads_elt_pipeline', 'airbyte_sync.trigger_connection_sync', 'scheduled__2025-04-09T00:00:00+00:00', '--job-id', '398', '--raw', '--subdir', 'DAGS_FOLDER/meta_ads_elt_pipeline.py', '--cfg-path', '/tmp/tmplpnq2js6']
[2025-04-10T22:13:10.846+0000] {standard_task_runner.py:105} INFO - Job 398: Subtask airbyte_sync.trigger_connection_sync
[2025-04-10T22:13:10.889+0000] {task_command.py:467} INFO - Running <TaskInstance: meta_ads_elt_pipeline.airbyte_sync.trigger_connection_sync scheduled__2025-04-09T00:00:00+00:00 [running]> on host ffa99f2ae5fe
[2025-04-10T22:13:10.955+0000] {taskinstance.py:3134} INFO - Exporting env vars: AIRFLOW_CTX_DAG_OWNER='admin' AIRFLOW_CTX_DAG_ID='meta_ads_elt_pipeline' AIRFLOW_CTX_TASK_ID='airbyte_sync.trigger_connection_sync' AIRFLOW_CTX_EXECUTION_DATE='2025-04-09T00:00:00+00:00' AIRFLOW_CTX_TRY_NUMBER='1' AIRFLOW_CTX_DAG_RUN_ID='scheduled__2025-04-09T00:00:00+00:00'
[2025-04-10T22:13:10.957+0000] {logging_mixin.py:190} INFO - Task instance is in running state
[2025-04-10T22:13:10.958+0000] {logging_mixin.py:190} INFO -  Previous state of the Task instance: queued
[2025-04-10T22:13:10.958+0000] {logging_mixin.py:190} INFO - Current task name:airbyte_sync.trigger_connection_sync state:running start_date:2025-04-10 22:13:10.814328+00:00
[2025-04-10T22:13:10.958+0000] {logging_mixin.py:190} INFO - Dag name:meta_ads_elt_pipeline and current dag run status:running
[2025-04-10T22:13:10.958+0000] {taskinstance.py:732} INFO - ::endgroup::
[2025-04-10T22:13:10.958+0000] {http.py:180} INFO - Calling HTTP method
[2025-04-10T22:13:10.966+0000] {base.py:84} INFO - Retrieving connection 'airbyte'
[2025-04-10T22:13:10.974+0000] {base.py:84} INFO - Retrieving connection 'airbyte'
[2025-04-10T22:13:11.433+0000] {http.py:241} INFO - {"job":{"id":276,"configType":"sync","configId":"29c579af-667a-4bca-a9ab-12f750e68c02","enabledStreams":[{"name":"campaigns"},{"name":"ad_sets"},{"name":"ad_creatives"},{"name":"ads"}],"createdAt":1744323191,"updatedAt":1744323191,"status":"running","streamAggregatedStats":[]},"attempts":[{"attempt":{"id":0,"status":"running","createdAt":1744323191,"updatedAt":1744323191},"logType":"formatted","logs":{"events":[],"logLines":[]}}]}
[2025-04-10T22:13:11.458+0000] {taskinstance.py:341} INFO - ::group::Post task execution logs
[2025-04-10T22:13:11.459+0000] {taskinstance.py:353} INFO - Marking task as SUCCESS. dag_id=meta_ads_elt_pipeline, task_id=airbyte_sync.trigger_connection_sync, run_id=scheduled__2025-04-09T00:00:00+00:00, execution_date=20250409T000000, start_date=20250410T221310, end_date=20250410T221311
[2025-04-10T22:13:11.507+0000] {logging_mixin.py:190} INFO - Task instance in success state
[2025-04-10T22:13:11.507+0000] {logging_mixin.py:190} INFO -  Previous state of the Task instance: running
[2025-04-10T22:13:11.507+0000] {logging_mixin.py:190} INFO - Dag name:meta_ads_elt_pipeline queued_at:2025-04-10 22:13:09.580624+00:00
[2025-04-10T22:13:11.507+0000] {logging_mixin.py:190} INFO - Task hostname:ffa99f2ae5fe operator:HttpOperator
[2025-04-10T22:13:11.537+0000] {local_task_job_runner.py:266} INFO - Task exited with return code 0
[2025-04-10T22:13:11.568+0000] {taskinstance.py:3901} INFO - 1 downstream tasks scheduled from follow-on schedule check
[2025-04-10T22:13:11.569+0000] {local_task_job_runner.py:245} INFO - ::endgroup::
