[2025-03-26T18:09:54.148+0000] {local_task_job_runner.py:123} INFO - ::group::Pre task execution logs
[2025-03-26T18:09:54.165+0000] {taskinstance.py:2614} INFO - Dependencies all met for dep_context=non-requeueable deps ti=<TaskInstance: running_airbyte.tst manual__2025-03-26T18:09:52.139135+00:00 [queued]>
[2025-03-26T18:09:54.170+0000] {taskinstance.py:2614} INFO - Dependencies all met for dep_context=requeueable deps ti=<TaskInstance: running_airbyte.tst manual__2025-03-26T18:09:52.139135+00:00 [queued]>
[2025-03-26T18:09:54.171+0000] {taskinstance.py:2867} INFO - Starting attempt 1 of 1
[2025-03-26T18:09:54.181+0000] {taskinstance.py:2890} INFO - Executing <Task(HttpOperator): tst> on 2025-03-26 18:09:52.139135+00:00
[2025-03-26T18:09:54.194+0000] {warnings.py:112} WARNING - /home/***/.local/lib/python3.12/site-packages/***/task/task_runner/standard_task_runner.py:70: DeprecationWarning: This process (pid=603) is multi-threaded, use of fork() may lead to deadlocks in the child.
  pid = os.fork()

[2025-03-26T18:09:54.195+0000] {standard_task_runner.py:72} INFO - Started process 605 to run task
[2025-03-26T18:09:54.197+0000] {standard_task_runner.py:104} INFO - Running: ['***', 'tasks', 'run', 'running_airbyte', 'tst', 'manual__2025-03-26T18:09:52.139135+00:00', '--job-id', '53', '--raw', '--subdir', 'DAGS_FOLDER/meta_ads_dag.py', '--cfg-path', '/tmp/tmpmqnarna7']
[2025-03-26T18:09:54.198+0000] {standard_task_runner.py:105} INFO - Job 53: Subtask tst
[2025-03-26T18:09:54.254+0000] {task_command.py:467} INFO - Running <TaskInstance: running_airbyte.tst manual__2025-03-26T18:09:52.139135+00:00 [running]> on host 929e032a3063
[2025-03-26T18:09:54.324+0000] {taskinstance.py:3134} INFO - Exporting env vars: AIRFLOW_CTX_DAG_OWNER='***' AIRFLOW_CTX_DAG_ID='running_airbyte' AIRFLOW_CTX_TASK_ID='tst' AIRFLOW_CTX_EXECUTION_DATE='2025-03-26T18:09:52.139135+00:00' AIRFLOW_CTX_TRY_NUMBER='1' AIRFLOW_CTX_DAG_RUN_ID='manual__2025-03-26T18:09:52.139135+00:00'
[2025-03-26T18:09:54.326+0000] {logging_mixin.py:190} INFO - Task instance is in running state
[2025-03-26T18:09:54.326+0000] {logging_mixin.py:190} INFO -  Previous state of the Task instance: queued
[2025-03-26T18:09:54.326+0000] {logging_mixin.py:190} INFO - Current task name:tst state:running start_date:2025-03-26 18:09:54.165564+00:00
[2025-03-26T18:09:54.326+0000] {logging_mixin.py:190} INFO - Dag name:running_airbyte and current dag run status:running
[2025-03-26T18:09:54.326+0000] {taskinstance.py:732} INFO - ::endgroup::
[2025-03-26T18:09:54.326+0000] {http.py:180} INFO - Calling HTTP method
[2025-03-26T18:09:54.333+0000] {base.py:84} INFO - Retrieving connection 'airbyte'
[2025-03-26T18:09:54.339+0000] {base.py:84} INFO - Retrieving connection 'airbyte'
[2025-03-26T18:09:54.344+0000] {http.py:278} ERROR - HTTP error: Not Allowed
[2025-03-26T18:09:54.344+0000] {http.py:279} ERROR - <html>
<head><title>405 Not Allowed</title></head>
<body>
<center><h1>405 Not Allowed</h1></center>
<hr><center>nginx/1.27.2</center>
</body>
</html>

[2025-03-26T18:09:54.352+0000] {taskinstance.py:3313} ERROR - Task failed with exception
Traceback (most recent call last):
  File "/home/airflow/.local/lib/python3.12/site-packages/airflow/providers/http/hooks/http.py", line 276, in check_response
    response.raise_for_status()
  File "/home/airflow/.local/lib/python3.12/site-packages/requests/models.py", line 1024, in raise_for_status
    raise HTTPError(http_error_msg, response=self)
requests.exceptions.HTTPError: 405 Client Error: Not Allowed for url: http://192.168.1.130:8000/v1/jobs

During handling of the above exception, another exception occurred:

Traceback (most recent call last):
  File "/home/airflow/.local/lib/python3.12/site-packages/airflow/models/taskinstance.py", line 768, in _execute_task
    result = _execute_callable(context=context, **execute_callable_kwargs)
             ^^^^^^^^^^^^^^^^^^^^^^^^^^^^^^^^^^^^^^^^^^^^^^^^^^^^^^^^^^^^^
  File "/home/airflow/.local/lib/python3.12/site-packages/airflow/models/taskinstance.py", line 734, in _execute_callable
    return ExecutionCallableRunner(
           ^^^^^^^^^^^^^^^^^^^^^^^^
  File "/home/airflow/.local/lib/python3.12/site-packages/airflow/utils/operator_helpers.py", line 252, in run
    return self.func(*args, **kwargs)
           ^^^^^^^^^^^^^^^^^^^^^^^^^^
  File "/home/airflow/.local/lib/python3.12/site-packages/airflow/models/baseoperator.py", line 424, in wrapper
    return func(self, *args, **kwargs)
           ^^^^^^^^^^^^^^^^^^^^^^^^^^^
  File "/home/airflow/.local/lib/python3.12/site-packages/airflow/providers/http/operators/http.py", line 177, in execute
    return self.execute_sync(context=context)
           ^^^^^^^^^^^^^^^^^^^^^^^^^^^^^^^^^^
  File "/home/airflow/.local/lib/python3.12/site-packages/airflow/providers/http/operators/http.py", line 191, in execute_sync
    response = self.hook.run(
               ^^^^^^^^^^^^^^
  File "/home/airflow/.local/lib/python3.12/site-packages/airflow/providers/http/hooks/http.py", line 265, in run
    return self.run_and_check(session, prepped_request, extra_options)
           ^^^^^^^^^^^^^^^^^^^^^^^^^^^^^^^^^^^^^^^^^^^^^^^^^^^^^^^^^^^
  File "/home/airflow/.local/lib/python3.12/site-packages/airflow/providers/http/hooks/http.py", line 318, in run_and_check
    self.check_response(response)
  File "/home/airflow/.local/lib/python3.12/site-packages/airflow/providers/http/hooks/http.py", line 280, in check_response
    raise AirflowException(str(response.status_code) + ":" + response.reason)
airflow.exceptions.AirflowException: 405:Not Allowed
[2025-03-26T18:09:54.356+0000] {logging_mixin.py:190} INFO - Task instance in failure state
[2025-03-26T18:09:54.356+0000] {logging_mixin.py:190} INFO - Task start:2025-03-26 18:09:54.165564+00:00 end:2025-03-26 18:09:54.355702+00:00 duration:0.190138
[2025-03-26T18:09:54.356+0000] {logging_mixin.py:190} INFO - Task:<Task(HttpOperator): tst> dag:<DAG: running_airbyte> dagrun:<DagRun running_airbyte @ 2025-03-26 18:09:52.139135+00:00: manual__2025-03-26T18:09:52.139135+00:00, state:running, queued_at: 2025-03-26 18:09:52.149299+00:00. externally triggered: True>
[2025-03-26T18:09:54.356+0000] {logging_mixin.py:190} INFO - Failure caused by 405:Not Allowed
[2025-03-26T18:09:54.356+0000] {taskinstance.py:1226} INFO - Marking task as FAILED. dag_id=running_airbyte, task_id=tst, run_id=manual__2025-03-26T18:09:52.139135+00:00, execution_date=20250326T180952, start_date=20250326T180954, end_date=20250326T180954
[2025-03-26T18:09:54.379+0000] {taskinstance.py:341} INFO - ::group::Post task execution logs
[2025-03-26T18:09:54.380+0000] {standard_task_runner.py:124} ERROR - Failed to execute job 53 for task tst (405:Not Allowed; 605)
Traceback (most recent call last):
  File "/home/airflow/.local/lib/python3.12/site-packages/airflow/providers/http/hooks/http.py", line 276, in check_response
    response.raise_for_status()
  File "/home/airflow/.local/lib/python3.12/site-packages/requests/models.py", line 1024, in raise_for_status
    raise HTTPError(http_error_msg, response=self)
requests.exceptions.HTTPError: 405 Client Error: Not Allowed for url: http://192.168.1.130:8000/v1/jobs

During handling of the above exception, another exception occurred:

Traceback (most recent call last):
  File "/home/airflow/.local/lib/python3.12/site-packages/airflow/task/task_runner/standard_task_runner.py", line 117, in _start_by_fork
    ret = args.func(args, dag=self.dag)
          ^^^^^^^^^^^^^^^^^^^^^^^^^^^^^
  File "/home/airflow/.local/lib/python3.12/site-packages/airflow/cli/cli_config.py", line 49, in command
    return func(*args, **kwargs)
           ^^^^^^^^^^^^^^^^^^^^^
  File "/home/airflow/.local/lib/python3.12/site-packages/airflow/utils/cli.py", line 116, in wrapper
    return f(*args, **kwargs)
           ^^^^^^^^^^^^^^^^^^
  File "/home/airflow/.local/lib/python3.12/site-packages/airflow/cli/commands/task_command.py", line 483, in task_run
    task_return_code = _run_task_by_selected_method(args, _dag, ti)
                       ^^^^^^^^^^^^^^^^^^^^^^^^^^^^^^^^^^^^^^^^^^^^
  File "/home/airflow/.local/lib/python3.12/site-packages/airflow/cli/commands/task_command.py", line 256, in _run_task_by_selected_method
    return _run_raw_task(args, ti)
           ^^^^^^^^^^^^^^^^^^^^^^^
  File "/home/airflow/.local/lib/python3.12/site-packages/airflow/cli/commands/task_command.py", line 341, in _run_raw_task
    return ti._run_raw_task(
           ^^^^^^^^^^^^^^^^^
  File "/home/airflow/.local/lib/python3.12/site-packages/airflow/utils/session.py", line 97, in wrapper
    return func(*args, session=session, **kwargs)
           ^^^^^^^^^^^^^^^^^^^^^^^^^^^^^^^^^^^^^^
  File "/home/airflow/.local/lib/python3.12/site-packages/airflow/models/taskinstance.py", line 3006, in _run_raw_task
    return _run_raw_task(
           ^^^^^^^^^^^^^^
  File "/home/airflow/.local/lib/python3.12/site-packages/airflow/models/taskinstance.py", line 274, in _run_raw_task
    TaskInstance._execute_task_with_callbacks(
  File "/home/airflow/.local/lib/python3.12/site-packages/airflow/models/taskinstance.py", line 3161, in _execute_task_with_callbacks
    result = self._execute_task(context, task_orig)
             ^^^^^^^^^^^^^^^^^^^^^^^^^^^^^^^^^^^^^^
  File "/home/airflow/.local/lib/python3.12/site-packages/airflow/models/taskinstance.py", line 3185, in _execute_task
    return _execute_task(self, context, task_orig)
           ^^^^^^^^^^^^^^^^^^^^^^^^^^^^^^^^^^^^^^^
  File "/home/airflow/.local/lib/python3.12/site-packages/airflow/models/taskinstance.py", line 768, in _execute_task
    result = _execute_callable(context=context, **execute_callable_kwargs)
             ^^^^^^^^^^^^^^^^^^^^^^^^^^^^^^^^^^^^^^^^^^^^^^^^^^^^^^^^^^^^^
  File "/home/airflow/.local/lib/python3.12/site-packages/airflow/models/taskinstance.py", line 734, in _execute_callable
    return ExecutionCallableRunner(
           ^^^^^^^^^^^^^^^^^^^^^^^^
  File "/home/airflow/.local/lib/python3.12/site-packages/airflow/utils/operator_helpers.py", line 252, in run
    return self.func(*args, **kwargs)
           ^^^^^^^^^^^^^^^^^^^^^^^^^^
  File "/home/airflow/.local/lib/python3.12/site-packages/airflow/models/baseoperator.py", line 424, in wrapper
    return func(self, *args, **kwargs)
           ^^^^^^^^^^^^^^^^^^^^^^^^^^^
  File "/home/airflow/.local/lib/python3.12/site-packages/airflow/providers/http/operators/http.py", line 177, in execute
    return self.execute_sync(context=context)
           ^^^^^^^^^^^^^^^^^^^^^^^^^^^^^^^^^^
  File "/home/airflow/.local/lib/python3.12/site-packages/airflow/providers/http/operators/http.py", line 191, in execute_sync
    response = self.hook.run(
               ^^^^^^^^^^^^^^
  File "/home/airflow/.local/lib/python3.12/site-packages/airflow/providers/http/hooks/http.py", line 265, in run
    return self.run_and_check(session, prepped_request, extra_options)
           ^^^^^^^^^^^^^^^^^^^^^^^^^^^^^^^^^^^^^^^^^^^^^^^^^^^^^^^^^^^
  File "/home/airflow/.local/lib/python3.12/site-packages/airflow/providers/http/hooks/http.py", line 318, in run_and_check
    self.check_response(response)
  File "/home/airflow/.local/lib/python3.12/site-packages/airflow/providers/http/hooks/http.py", line 280, in check_response
    raise AirflowException(str(response.status_code) + ":" + response.reason)
airflow.exceptions.AirflowException: 405:Not Allowed
[2025-03-26T18:09:54.409+0000] {local_task_job_runner.py:266} INFO - Task exited with return code 1
[2025-03-26T18:09:54.421+0000] {taskinstance.py:3901} INFO - 0 downstream tasks scheduled from follow-on schedule check
[2025-03-26T18:09:54.422+0000] {local_task_job_runner.py:245} INFO - ::endgroup::
