[2025-03-26T17:03:52.633+0000] {local_task_job_runner.py:123} INFO - ::group::Pre task execution logs
[2025-03-26T17:03:52.649+0000] {taskinstance.py:2614} INFO - Dependencies all met for dep_context=non-requeueable deps ti=<TaskInstance: trigger_airbyte_job_example.airbyte_metaads manual__2025-03-26T17:03:49.613594+00:00 [queued]>
[2025-03-26T17:03:52.654+0000] {taskinstance.py:2614} INFO - Dependencies all met for dep_context=requeueable deps ti=<TaskInstance: trigger_airbyte_job_example.airbyte_metaads manual__2025-03-26T17:03:49.613594+00:00 [queued]>
[2025-03-26T17:03:52.654+0000] {taskinstance.py:2867} INFO - Starting attempt 1 of 1
[2025-03-26T17:03:52.665+0000] {taskinstance.py:2890} INFO - Executing <Task(AirbyteTriggerSyncOperator): airbyte_metaads> on 2025-03-26 17:03:49.613594+00:00
[2025-03-26T17:03:52.678+0000] {warnings.py:112} WARNING - /home/***/.local/lib/python3.12/site-packages/***/task/task_runner/standard_task_runner.py:70: DeprecationWarning: This process (pid=1360) is multi-threaded, use of fork() may lead to deadlocks in the child.
  pid = os.fork()

[2025-03-26T17:03:52.679+0000] {standard_task_runner.py:72} INFO - Started process 1362 to run task
[2025-03-26T17:03:52.679+0000] {standard_task_runner.py:104} INFO - Running: ['***', 'tasks', 'run', 'trigger_airbyte_job_example', 'airbyte_metaads', 'manual__2025-03-26T17:03:49.613594+00:00', '--job-id', '29', '--raw', '--subdir', 'DAGS_FOLDER/meta_ads_dag.py', '--cfg-path', '/tmp/tmp30o8pxpc']
[2025-03-26T17:03:52.680+0000] {standard_task_runner.py:105} INFO - Job 29: Subtask airbyte_metaads
[2025-03-26T17:03:52.726+0000] {task_command.py:467} INFO - Running <TaskInstance: trigger_airbyte_job_example.airbyte_metaads manual__2025-03-26T17:03:49.613594+00:00 [running]> on host e3e3ae5ea89f
[2025-03-26T17:03:52.793+0000] {taskinstance.py:3134} INFO - Exporting env vars: AIRFLOW_CTX_DAG_OWNER='***' AIRFLOW_CTX_DAG_ID='trigger_airbyte_job_example' AIRFLOW_CTX_TASK_ID='airbyte_metaads' AIRFLOW_CTX_EXECUTION_DATE='2025-03-26T17:03:49.613594+00:00' AIRFLOW_CTX_TRY_NUMBER='1' AIRFLOW_CTX_DAG_RUN_ID='manual__2025-03-26T17:03:49.613594+00:00'
[2025-03-26T17:03:52.794+0000] {logging_mixin.py:190} INFO - Task instance is in running state
[2025-03-26T17:03:52.795+0000] {logging_mixin.py:190} INFO -  Previous state of the Task instance: queued
[2025-03-26T17:03:52.795+0000] {logging_mixin.py:190} INFO - Current task name:airbyte_metaads state:running start_date:2025-03-26 17:03:52.649303+00:00
[2025-03-26T17:03:52.795+0000] {logging_mixin.py:190} INFO - Dag name:trigger_airbyte_job_example and current dag run status:running
[2025-03-26T17:03:52.795+0000] {taskinstance.py:732} INFO - ::endgroup::
[2025-03-26T17:03:52.804+0000] {base.py:84} INFO - Retrieving connection 'airbyte_conn'
[2025-03-26T17:03:52.882+0000] {taskinstance.py:3313} ERROR - Task failed with exception
Traceback (most recent call last):
  File "/home/airflow/.local/lib/python3.12/site-packages/urllib3/connection.py", line 198, in _new_conn
    sock = connection.create_connection(
           ^^^^^^^^^^^^^^^^^^^^^^^^^^^^^
  File "/home/airflow/.local/lib/python3.12/site-packages/urllib3/util/connection.py", line 60, in create_connection
    for res in socket.getaddrinfo(host, port, family, socket.SOCK_STREAM):
               ^^^^^^^^^^^^^^^^^^^^^^^^^^^^^^^^^^^^^^^^^^^^^^^^^^^^^^^^^^
  File "/usr/local/lib/python3.12/socket.py", line 978, in getaddrinfo
    for res in _socket.getaddrinfo(host, port, family, type, proto, flags):
               ^^^^^^^^^^^^^^^^^^^^^^^^^^^^^^^^^^^^^^^^^^^^^^^^^^^^^^^^^^^
socket.gaierror: [Errno -2] Name or service not known

The above exception was the direct cause of the following exception:

Traceback (most recent call last):
  File "/home/airflow/.local/lib/python3.12/site-packages/urllib3/connectionpool.py", line 787, in urlopen
    response = self._make_request(
               ^^^^^^^^^^^^^^^^^^^
  File "/home/airflow/.local/lib/python3.12/site-packages/urllib3/connectionpool.py", line 493, in _make_request
    conn.request(
  File "/home/airflow/.local/lib/python3.12/site-packages/urllib3/connection.py", line 445, in request
    self.endheaders()
  File "/usr/local/lib/python3.12/http/client.py", line 1333, in endheaders
    self._send_output(message_body, encode_chunked=encode_chunked)
  File "/usr/local/lib/python3.12/http/client.py", line 1093, in _send_output
    self.send(msg)
  File "/usr/local/lib/python3.12/http/client.py", line 1037, in send
    self.connect()
  File "/home/airflow/.local/lib/python3.12/site-packages/urllib3/connection.py", line 276, in connect
    self.sock = self._new_conn()
                ^^^^^^^^^^^^^^^^
  File "/home/airflow/.local/lib/python3.12/site-packages/urllib3/connection.py", line 205, in _new_conn
    raise NameResolutionError(self.host, self, e) from e
urllib3.exceptions.NameResolutionError: <urllib3.connection.HTTPConnection object at 0x751bf90648c0>: Failed to resolve 'host.docker.internal' ([Errno -2] Name or service not known)

The above exception was the direct cause of the following exception:

Traceback (most recent call last):
  File "/home/airflow/.local/lib/python3.12/site-packages/requests/adapters.py", line 667, in send
    resp = conn.urlopen(
           ^^^^^^^^^^^^^
  File "/home/airflow/.local/lib/python3.12/site-packages/urllib3/connectionpool.py", line 841, in urlopen
    retries = retries.increment(
              ^^^^^^^^^^^^^^^^^^
  File "/home/airflow/.local/lib/python3.12/site-packages/urllib3/util/retry.py", line 519, in increment
    raise MaxRetryError(_pool, url, reason) from reason  # type: ignore[arg-type]
    ^^^^^^^^^^^^^^^^^^^^^^^^^^^^^^^^^^^^^^^^^^^^^^^^^^^
urllib3.exceptions.MaxRetryError: HTTPConnectionPool(host='host.docker.internal', port=80): Max retries exceeded with url: /v1/applications/token (Caused by NameResolutionError("<urllib3.connection.HTTPConnection object at 0x751bf90648c0>: Failed to resolve 'host.docker.internal' ([Errno -2] Name or service not known)"))

During handling of the above exception, another exception occurred:

Traceback (most recent call last):
  File "/home/airflow/.local/lib/python3.12/site-packages/airflow/providers/airbyte/hooks/airbyte.py", line 157, in submit_sync_connection
    res = self.airbyte_api.jobs.create_job(
          ^^^^^^^^^^^^^^^^^^^^^^^^^^^^^^^^^
  File "/home/airflow/.local/lib/python3.12/site-packages/airbyte_api/jobs.py", line 100, in create_job
    raise e
  File "/home/airflow/.local/lib/python3.12/site-packages/airbyte_api/jobs.py", line 95, in create_job
    req = self.sdk_configuration.get_hooks().before_request(BeforeRequestContext(hook_ctx), req)
          ^^^^^^^^^^^^^^^^^^^^^^^^^^^^^^^^^^^^^^^^^^^^^^^^^^^^^^^^^^^^^^^^^^^^^^^^^^^^^^^^^^^^^^
  File "/home/airflow/.local/lib/python3.12/site-packages/airbyte_api/_hooks/sdkhooks.py", line 41, in before_request
    out = hook.before_request(hook_ctx, request)
          ^^^^^^^^^^^^^^^^^^^^^^^^^^^^^^^^^^^^^^
  File "/home/airflow/.local/lib/python3.12/site-packages/airbyte_api/_hooks/clientcredentials.py", line 59, in before_request
    sess = self.do_token_request(credentials, self.get_scopes(
           ^^^^^^^^^^^^^^^^^^^^^^^^^^^^^^^^^^^^^^^^^^^^^^^^^^^
  File "/home/airflow/.local/lib/python3.12/site-packages/airbyte_api/_hooks/clientcredentials.py", line 119, in do_token_request
    response = self.client.post(token_url, data=payload)
               ^^^^^^^^^^^^^^^^^^^^^^^^^^^^^^^^^^^^^^^^^
  File "/home/airflow/.local/lib/python3.12/site-packages/requests/sessions.py", line 637, in post
    return self.request("POST", url, data=data, json=json, **kwargs)
           ^^^^^^^^^^^^^^^^^^^^^^^^^^^^^^^^^^^^^^^^^^^^^^^^^^^^^^^^^
  File "/home/airflow/.local/lib/python3.12/site-packages/requests/sessions.py", line 589, in request
    resp = self.send(prep, **send_kwargs)
           ^^^^^^^^^^^^^^^^^^^^^^^^^^^^^^
  File "/home/airflow/.local/lib/python3.12/site-packages/requests/sessions.py", line 703, in send
    r = adapter.send(request, **kwargs)
        ^^^^^^^^^^^^^^^^^^^^^^^^^^^^^^^
  File "/home/airflow/.local/lib/python3.12/site-packages/requests/adapters.py", line 700, in send
    raise ConnectionError(e, request=request)
requests.exceptions.ConnectionError: HTTPConnectionPool(host='host.docker.internal', port=80): Max retries exceeded with url: /v1/applications/token (Caused by NameResolutionError("<urllib3.connection.HTTPConnection object at 0x751bf90648c0>: Failed to resolve 'host.docker.internal' ([Errno -2] Name or service not known)"))

During handling of the above exception, another exception occurred:

Traceback (most recent call last):
  File "/home/airflow/.local/lib/python3.12/site-packages/airflow/models/taskinstance.py", line 768, in _execute_task
    result = _execute_callable(context=context, **execute_callable_kwargs)
             ^^^^^^^^^^^^^^^^^^^^^^^^^^^^^^^^^^^^^^^^^^^^^^^^^^^^^^^^^^^^^
  File "/home/airflow/.local/lib/python3.12/site-packages/airflow/models/taskinstance.py", line 734, in _execute_callable
    return ExecutionCallableRunner(
           ^^^^^^^^^^^^^^^^^^^^^^^^
  File "/home/airflow/.local/lib/python3.12/site-packages/airflow/utils/operator_helpers.py", line 252, in run
    return self.func(*args, **kwargs)
           ^^^^^^^^^^^^^^^^^^^^^^^^^^
  File "/home/airflow/.local/lib/python3.12/site-packages/airflow/models/baseoperator.py", line 424, in wrapper
    return func(self, *args, **kwargs)
           ^^^^^^^^^^^^^^^^^^^^^^^^^^^
  File "/home/airflow/.local/lib/python3.12/site-packages/airflow/providers/airbyte/operators/airbyte.py", line 84, in execute
    job_object = hook.submit_sync_connection(connection_id=self.connection_id)
                 ^^^^^^^^^^^^^^^^^^^^^^^^^^^^^^^^^^^^^^^^^^^^^^^^^^^^^^^^^^^^^
  File "/home/airflow/.local/lib/python3.12/site-packages/airflow/providers/airbyte/hooks/airbyte.py", line 165, in submit_sync_connection
    raise AirflowException(e)
airflow.exceptions.AirflowException: HTTPConnectionPool(host='host.docker.internal', port=80): Max retries exceeded with url: /v1/applications/token (Caused by NameResolutionError("<urllib3.connection.HTTPConnection object at 0x751bf90648c0>: Failed to resolve 'host.docker.internal' ([Errno -2] Name or service not known)"))
[2025-03-26T17:03:52.900+0000] {logging_mixin.py:190} INFO - Task instance in failure state
[2025-03-26T17:03:52.901+0000] {logging_mixin.py:190} INFO - Task start:2025-03-26 17:03:52.649303+00:00 end:2025-03-26 17:03:52.900275+00:00 duration:0.250972
[2025-03-26T17:03:52.901+0000] {logging_mixin.py:190} INFO - Task:<Task(AirbyteTriggerSyncOperator): airbyte_metaads> dag:<DAG: trigger_airbyte_job_example> dagrun:<DagRun trigger_airbyte_job_example @ 2025-03-26 17:03:49.613594+00:00: manual__2025-03-26T17:03:49.613594+00:00, state:running, queued_at: 2025-03-26 17:03:49.623149+00:00. externally triggered: True>
[2025-03-26T17:03:52.902+0000] {logging_mixin.py:190} INFO - Failure caused by HTTPConnectionPool(host='host.docker.internal', port=80): Max retries exceeded with url: /v1/applications/token (Caused by NameResolutionError("<urllib3.connection.HTTPConnection object at 0x751bf90648c0>: Failed to resolve 'host.docker.internal' ([Errno -2] Name or service not known)"))
[2025-03-26T17:03:52.902+0000] {taskinstance.py:1226} INFO - Marking task as FAILED. dag_id=trigger_airbyte_job_example, task_id=airbyte_metaads, run_id=manual__2025-03-26T17:03:49.613594+00:00, execution_date=20250326T170349, start_date=20250326T170352, end_date=20250326T170352
[2025-03-26T17:03:52.932+0000] {taskinstance.py:341} INFO - ::group::Post task execution logs
[2025-03-26T17:03:52.933+0000] {standard_task_runner.py:124} ERROR - Failed to execute job 29 for task airbyte_metaads (HTTPConnectionPool(host='host.docker.internal', port=80): Max retries exceeded with url: /v1/applications/token (Caused by NameResolutionError("<urllib3.connection.HTTPConnection object at 0x751bf90648c0>: Failed to resolve 'host.docker.internal' ([Errno -2] Name or service not known)")); 1362)
Traceback (most recent call last):
  File "/home/airflow/.local/lib/python3.12/site-packages/urllib3/connection.py", line 198, in _new_conn
    sock = connection.create_connection(
           ^^^^^^^^^^^^^^^^^^^^^^^^^^^^^
  File "/home/airflow/.local/lib/python3.12/site-packages/urllib3/util/connection.py", line 60, in create_connection
    for res in socket.getaddrinfo(host, port, family, socket.SOCK_STREAM):
               ^^^^^^^^^^^^^^^^^^^^^^^^^^^^^^^^^^^^^^^^^^^^^^^^^^^^^^^^^^
  File "/usr/local/lib/python3.12/socket.py", line 978, in getaddrinfo
    for res in _socket.getaddrinfo(host, port, family, type, proto, flags):
               ^^^^^^^^^^^^^^^^^^^^^^^^^^^^^^^^^^^^^^^^^^^^^^^^^^^^^^^^^^^
socket.gaierror: [Errno -2] Name or service not known

The above exception was the direct cause of the following exception:

Traceback (most recent call last):
  File "/home/airflow/.local/lib/python3.12/site-packages/urllib3/connectionpool.py", line 787, in urlopen
    response = self._make_request(
               ^^^^^^^^^^^^^^^^^^^
  File "/home/airflow/.local/lib/python3.12/site-packages/urllib3/connectionpool.py", line 493, in _make_request
    conn.request(
  File "/home/airflow/.local/lib/python3.12/site-packages/urllib3/connection.py", line 445, in request
    self.endheaders()
  File "/usr/local/lib/python3.12/http/client.py", line 1333, in endheaders
    self._send_output(message_body, encode_chunked=encode_chunked)
  File "/usr/local/lib/python3.12/http/client.py", line 1093, in _send_output
    self.send(msg)
  File "/usr/local/lib/python3.12/http/client.py", line 1037, in send
    self.connect()
  File "/home/airflow/.local/lib/python3.12/site-packages/urllib3/connection.py", line 276, in connect
    self.sock = self._new_conn()
                ^^^^^^^^^^^^^^^^
  File "/home/airflow/.local/lib/python3.12/site-packages/urllib3/connection.py", line 205, in _new_conn
    raise NameResolutionError(self.host, self, e) from e
urllib3.exceptions.NameResolutionError: <urllib3.connection.HTTPConnection object at 0x751bf90648c0>: Failed to resolve 'host.docker.internal' ([Errno -2] Name or service not known)

The above exception was the direct cause of the following exception:

Traceback (most recent call last):
  File "/home/airflow/.local/lib/python3.12/site-packages/requests/adapters.py", line 667, in send
    resp = conn.urlopen(
           ^^^^^^^^^^^^^
  File "/home/airflow/.local/lib/python3.12/site-packages/urllib3/connectionpool.py", line 841, in urlopen
    retries = retries.increment(
              ^^^^^^^^^^^^^^^^^^
  File "/home/airflow/.local/lib/python3.12/site-packages/urllib3/util/retry.py", line 519, in increment
    raise MaxRetryError(_pool, url, reason) from reason  # type: ignore[arg-type]
    ^^^^^^^^^^^^^^^^^^^^^^^^^^^^^^^^^^^^^^^^^^^^^^^^^^^
urllib3.exceptions.MaxRetryError: HTTPConnectionPool(host='host.docker.internal', port=80): Max retries exceeded with url: /v1/applications/token (Caused by NameResolutionError("<urllib3.connection.HTTPConnection object at 0x751bf90648c0>: Failed to resolve 'host.docker.internal' ([Errno -2] Name or service not known)"))

During handling of the above exception, another exception occurred:

Traceback (most recent call last):
  File "/home/airflow/.local/lib/python3.12/site-packages/airflow/providers/airbyte/hooks/airbyte.py", line 157, in submit_sync_connection
    res = self.airbyte_api.jobs.create_job(
          ^^^^^^^^^^^^^^^^^^^^^^^^^^^^^^^^^
  File "/home/airflow/.local/lib/python3.12/site-packages/airbyte_api/jobs.py", line 100, in create_job
    raise e
  File "/home/airflow/.local/lib/python3.12/site-packages/airbyte_api/jobs.py", line 95, in create_job
    req = self.sdk_configuration.get_hooks().before_request(BeforeRequestContext(hook_ctx), req)
          ^^^^^^^^^^^^^^^^^^^^^^^^^^^^^^^^^^^^^^^^^^^^^^^^^^^^^^^^^^^^^^^^^^^^^^^^^^^^^^^^^^^^^^
  File "/home/airflow/.local/lib/python3.12/site-packages/airbyte_api/_hooks/sdkhooks.py", line 41, in before_request
    out = hook.before_request(hook_ctx, request)
          ^^^^^^^^^^^^^^^^^^^^^^^^^^^^^^^^^^^^^^
  File "/home/airflow/.local/lib/python3.12/site-packages/airbyte_api/_hooks/clientcredentials.py", line 59, in before_request
    sess = self.do_token_request(credentials, self.get_scopes(
           ^^^^^^^^^^^^^^^^^^^^^^^^^^^^^^^^^^^^^^^^^^^^^^^^^^^
  File "/home/airflow/.local/lib/python3.12/site-packages/airbyte_api/_hooks/clientcredentials.py", line 119, in do_token_request
    response = self.client.post(token_url, data=payload)
               ^^^^^^^^^^^^^^^^^^^^^^^^^^^^^^^^^^^^^^^^^
  File "/home/airflow/.local/lib/python3.12/site-packages/requests/sessions.py", line 637, in post
    return self.request("POST", url, data=data, json=json, **kwargs)
           ^^^^^^^^^^^^^^^^^^^^^^^^^^^^^^^^^^^^^^^^^^^^^^^^^^^^^^^^^
  File "/home/airflow/.local/lib/python3.12/site-packages/requests/sessions.py", line 589, in request
    resp = self.send(prep, **send_kwargs)
           ^^^^^^^^^^^^^^^^^^^^^^^^^^^^^^
  File "/home/airflow/.local/lib/python3.12/site-packages/requests/sessions.py", line 703, in send
    r = adapter.send(request, **kwargs)
        ^^^^^^^^^^^^^^^^^^^^^^^^^^^^^^^
  File "/home/airflow/.local/lib/python3.12/site-packages/requests/adapters.py", line 700, in send
    raise ConnectionError(e, request=request)
requests.exceptions.ConnectionError: HTTPConnectionPool(host='host.docker.internal', port=80): Max retries exceeded with url: /v1/applications/token (Caused by NameResolutionError("<urllib3.connection.HTTPConnection object at 0x751bf90648c0>: Failed to resolve 'host.docker.internal' ([Errno -2] Name or service not known)"))

During handling of the above exception, another exception occurred:

Traceback (most recent call last):
  File "/home/airflow/.local/lib/python3.12/site-packages/airflow/task/task_runner/standard_task_runner.py", line 117, in _start_by_fork
    ret = args.func(args, dag=self.dag)
          ^^^^^^^^^^^^^^^^^^^^^^^^^^^^^
  File "/home/airflow/.local/lib/python3.12/site-packages/airflow/cli/cli_config.py", line 49, in command
    return func(*args, **kwargs)
           ^^^^^^^^^^^^^^^^^^^^^
  File "/home/airflow/.local/lib/python3.12/site-packages/airflow/utils/cli.py", line 116, in wrapper
    return f(*args, **kwargs)
           ^^^^^^^^^^^^^^^^^^
  File "/home/airflow/.local/lib/python3.12/site-packages/airflow/cli/commands/task_command.py", line 483, in task_run
    task_return_code = _run_task_by_selected_method(args, _dag, ti)
                       ^^^^^^^^^^^^^^^^^^^^^^^^^^^^^^^^^^^^^^^^^^^^
  File "/home/airflow/.local/lib/python3.12/site-packages/airflow/cli/commands/task_command.py", line 256, in _run_task_by_selected_method
    return _run_raw_task(args, ti)
           ^^^^^^^^^^^^^^^^^^^^^^^
  File "/home/airflow/.local/lib/python3.12/site-packages/airflow/cli/commands/task_command.py", line 341, in _run_raw_task
    return ti._run_raw_task(
           ^^^^^^^^^^^^^^^^^
  File "/home/airflow/.local/lib/python3.12/site-packages/airflow/utils/session.py", line 97, in wrapper
    return func(*args, session=session, **kwargs)
           ^^^^^^^^^^^^^^^^^^^^^^^^^^^^^^^^^^^^^^
  File "/home/airflow/.local/lib/python3.12/site-packages/airflow/models/taskinstance.py", line 3006, in _run_raw_task
    return _run_raw_task(
           ^^^^^^^^^^^^^^
  File "/home/airflow/.local/lib/python3.12/site-packages/airflow/models/taskinstance.py", line 274, in _run_raw_task
    TaskInstance._execute_task_with_callbacks(
  File "/home/airflow/.local/lib/python3.12/site-packages/airflow/models/taskinstance.py", line 3161, in _execute_task_with_callbacks
    result = self._execute_task(context, task_orig)
             ^^^^^^^^^^^^^^^^^^^^^^^^^^^^^^^^^^^^^^
  File "/home/airflow/.local/lib/python3.12/site-packages/airflow/models/taskinstance.py", line 3185, in _execute_task
    return _execute_task(self, context, task_orig)
           ^^^^^^^^^^^^^^^^^^^^^^^^^^^^^^^^^^^^^^^
  File "/home/airflow/.local/lib/python3.12/site-packages/airflow/models/taskinstance.py", line 768, in _execute_task
    result = _execute_callable(context=context, **execute_callable_kwargs)
             ^^^^^^^^^^^^^^^^^^^^^^^^^^^^^^^^^^^^^^^^^^^^^^^^^^^^^^^^^^^^^
  File "/home/airflow/.local/lib/python3.12/site-packages/airflow/models/taskinstance.py", line 734, in _execute_callable
    return ExecutionCallableRunner(
           ^^^^^^^^^^^^^^^^^^^^^^^^
  File "/home/airflow/.local/lib/python3.12/site-packages/airflow/utils/operator_helpers.py", line 252, in run
    return self.func(*args, **kwargs)
           ^^^^^^^^^^^^^^^^^^^^^^^^^^
  File "/home/airflow/.local/lib/python3.12/site-packages/airflow/models/baseoperator.py", line 424, in wrapper
    return func(self, *args, **kwargs)
           ^^^^^^^^^^^^^^^^^^^^^^^^^^^
  File "/home/airflow/.local/lib/python3.12/site-packages/airflow/providers/airbyte/operators/airbyte.py", line 84, in execute
    job_object = hook.submit_sync_connection(connection_id=self.connection_id)
                 ^^^^^^^^^^^^^^^^^^^^^^^^^^^^^^^^^^^^^^^^^^^^^^^^^^^^^^^^^^^^^
  File "/home/airflow/.local/lib/python3.12/site-packages/airflow/providers/airbyte/hooks/airbyte.py", line 165, in submit_sync_connection
    raise AirflowException(e)
airflow.exceptions.AirflowException: HTTPConnectionPool(host='host.docker.internal', port=80): Max retries exceeded with url: /v1/applications/token (Caused by NameResolutionError("<urllib3.connection.HTTPConnection object at 0x751bf90648c0>: Failed to resolve 'host.docker.internal' ([Errno -2] Name or service not known)"))
[2025-03-26T17:03:52.972+0000] {local_task_job_runner.py:266} INFO - Task exited with return code 1
[2025-03-26T17:03:52.994+0000] {taskinstance.py:3901} INFO - 0 downstream tasks scheduled from follow-on schedule check
[2025-03-26T17:03:52.997+0000] {local_task_job_runner.py:245} INFO - ::endgroup::
