[2025-04-07T13:39:33.833+0000] {local_task_job_runner.py:123} INFO - ::group::Pre task execution logs
[2025-04-07T13:39:33.849+0000] {taskinstance.py:2614} INFO - Dependencies all met for dep_context=non-requeueable deps ti=<TaskInstance: meta_ads_elt_pipeline.dbt_processing.data_transformations.meta_ads_ads_run manual__2025-04-07T13:37:14.373919+00:00 [queued]>
[2025-04-07T13:39:33.855+0000] {taskinstance.py:2614} INFO - Dependencies all met for dep_context=requeueable deps ti=<TaskInstance: meta_ads_elt_pipeline.dbt_processing.data_transformations.meta_ads_ads_run manual__2025-04-07T13:37:14.373919+00:00 [queued]>
[2025-04-07T13:39:33.855+0000] {taskinstance.py:2867} INFO - Starting attempt 3 of 3
[2025-04-07T13:39:33.864+0000] {taskinstance.py:2890} INFO - Executing <Task(DbtRunLocalOperator): dbt_processing.data_transformations.meta_ads_ads_run> on 2025-04-07 13:37:14.373919+00:00
[2025-04-07T13:39:33.876+0000] {warnings.py:112} WARNING - /home/***/.local/lib/python3.12/site-packages/***/task/task_runner/standard_task_runner.py:70: DeprecationWarning: This process (pid=9462) is multi-threaded, use of fork() may lead to deadlocks in the child.
  pid = os.fork()

[2025-04-07T13:39:33.877+0000] {standard_task_runner.py:72} INFO - Started process 9464 to run task
[2025-04-07T13:39:33.878+0000] {standard_task_runner.py:104} INFO - Running: ['***', 'tasks', 'run', 'meta_ads_elt_pipeline', 'dbt_processing.data_transformations.meta_ads_ads_run', 'manual__2025-04-07T13:37:14.373919+00:00', '--job-id', '169', '--raw', '--subdir', 'DAGS_FOLDER/meta_ads_dag.py', '--cfg-path', '/tmp/tmp_7o8wxiu']
[2025-04-07T13:39:33.879+0000] {standard_task_runner.py:105} INFO - Job 169: Subtask dbt_processing.data_transformations.meta_ads_ads_run
[2025-04-07T13:39:33.921+0000] {task_command.py:467} INFO - Running <TaskInstance: meta_ads_elt_pipeline.dbt_processing.data_transformations.meta_ads_ads_run manual__2025-04-07T13:37:14.373919+00:00 [running]> on host ffa99f2ae5fe
[2025-04-07T13:39:33.992+0000] {taskinstance.py:3134} INFO - Exporting env vars: AIRFLOW_CTX_DAG_OWNER='admin' AIRFLOW_CTX_DAG_ID='meta_ads_elt_pipeline' AIRFLOW_CTX_TASK_ID='dbt_processing.data_transformations.meta_ads_ads_run' AIRFLOW_CTX_EXECUTION_DATE='2025-04-07T13:37:14.373919+00:00' AIRFLOW_CTX_TRY_NUMBER='3' AIRFLOW_CTX_DAG_RUN_ID='manual__2025-04-07T13:37:14.373919+00:00'
[2025-04-07T13:39:33.994+0000] {logging_mixin.py:190} INFO - Task instance is in running state
[2025-04-07T13:39:33.994+0000] {logging_mixin.py:190} INFO -  Previous state of the Task instance: queued
[2025-04-07T13:39:33.994+0000] {logging_mixin.py:190} INFO - Current task name:dbt_processing.data_transformations.meta_ads_ads_run state:running start_date:2025-04-07 13:39:33.849412+00:00
[2025-04-07T13:39:33.995+0000] {logging_mixin.py:190} INFO - Dag name:meta_ads_elt_pipeline and current dag run status:running
[2025-04-07T13:39:33.995+0000] {taskinstance.py:732} INFO - ::endgroup::
[2025-04-07T13:39:34.989+0000] {local.py:213} INFO - dbtRunner is available. Using dbtRunner for invoking dbt.
[2025-04-07T13:39:34.990+0000] {local.py:416} INFO - Cloning project to writable temp directory /tmp/tmpbggfjsuf from /opt/airflow/dags/dbt/dbt_biera
[2025-04-07T13:39:34.990+0000] {local.py:427} INFO - Partial parse is enabled and the latest partial parse file is /tmp/cosmos/meta_ads_elt_pipeline__dbt_processing__data_transformations/target/partial_parse.msgpack
[2025-04-07T13:39:34.996+0000] {config.py:360} INFO - Profile caching is enable.
[2025-04-07T13:39:35.004+0000] {base.py:84} INFO - Retrieving connection 'postgres_conn'
[2025-04-07T13:39:35.005+0000] {config.py:340} INFO - Profile found in cache using profile: /tmp/cosmos/profile/c99bf486c96f06e0233408d45300d7cde96c22a7e21e1f49350115e2a86b810b/profiles.yml.
[2025-04-07T13:39:35.006+0000] {runner.py:60} INFO - Trying to run dbtRunner with:
 ['run', '--models', 'meta_ads_ads', '--full-refresh', '--project-dir', '/tmp/tmpbggfjsuf', '--profiles-dir', '/tmp/cosmos/profile/c99bf486c96f06e0233408d45300d7cde96c22a7e21e1f49350115e2a86b810b', '--profile', 'default', '--target', 'dev']
 in /tmp/tmpbggfjsuf
[2025-04-07T13:39:35.074+0000] {logging_mixin.py:190} INFO - 13:39:35  Running with dbt=1.9.3
[2025-04-07T13:39:35.295+0000] {logging_mixin.py:190} INFO - 13:39:35  Registered adapter: postgres=1.9.0
[2025-04-07T13:39:35.936+0000] {logging_mixin.py:190} INFO - 13:39:35  [WARNING]: Configuration paths exist in your dbt_project.yml file which do not apply to any resources.
There are 1 unused configuration paths:
- models.dbt_biera.analytics
[2025-04-07T13:39:36.257+0000] {logging_mixin.py:190} INFO - 13:39:36  Found 3 models, 4 sources, 434 macros
[2025-04-07T13:39:36.259+0000] {logging_mixin.py:190} INFO - 13:39:36
[2025-04-07T13:39:36.259+0000] {logging_mixin.py:190} INFO - 13:39:36  Concurrency: 1 threads (target='dev')
[2025-04-07T13:39:36.260+0000] {logging_mixin.py:190} INFO - 13:39:36
[2025-04-07T13:39:36.382+0000] {logging_mixin.py:190} INFO - 13:39:36  1 of 1 START sql view model staging.meta_ads_ads ............................... [RUN]
[2025-04-07T13:39:36.451+0000] {logging_mixin.py:190} INFO - 13:39:36  1 of 1 ERROR creating sql view model staging.meta_ads_ads ...................... [ERROR in 0.07s]
[2025-04-07T13:39:36.464+0000] {logging_mixin.py:190} INFO - 13:39:36
[2025-04-07T13:39:36.465+0000] {logging_mixin.py:190} INFO - 13:39:36  Finished running 1 view model in 0 hours 0 minutes and 0.20 seconds (0.20s).
[2025-04-07T13:39:36.492+0000] {logging_mixin.py:190} INFO - 13:39:36
[2025-04-07T13:39:36.493+0000] {logging_mixin.py:190} INFO - 13:39:36  Completed with 1 error, 0 partial successes, and 0 warnings:
[2025-04-07T13:39:36.493+0000] {logging_mixin.py:190} INFO - 13:39:36
[2025-04-07T13:39:36.494+0000] {logging_mixin.py:190} INFO - 13:39:36    Database Error in model meta_ads_ads (models/staging/meta_ads/meta_ads_ads.sql)
  column "adset_id" does not exist
  LINE 10:         adset_id,
                   ^
  compiled code at target/run/dbt_biera/models/staging/meta_ads/meta_ads_ads.sql
[2025-04-07T13:39:36.494+0000] {logging_mixin.py:190} INFO - 13:39:36
[2025-04-07T13:39:36.495+0000] {logging_mixin.py:190} INFO - 13:39:36  Done. PASS=0 WARN=0 ERROR=1 SKIP=0 TOTAL=1
[2025-04-07T13:39:37.047+0000] {local.py:465} INFO - Inlets: []
[2025-04-07T13:39:37.047+0000] {local.py:466} INFO - Outlets: []
[2025-04-07T13:39:37.048+0000] {local.py:656} INFO - Assigning inlets/outlets with DatasetAlias
[2025-04-07T13:39:37.067+0000] {taskinstance.py:3313} ERROR - Task failed with exception
Traceback (most recent call last):
  File "/home/airflow/.local/lib/python3.12/site-packages/airflow/models/taskinstance.py", line 768, in _execute_task
    result = _execute_callable(context=context, **execute_callable_kwargs)
             ^^^^^^^^^^^^^^^^^^^^^^^^^^^^^^^^^^^^^^^^^^^^^^^^^^^^^^^^^^^^^
  File "/home/airflow/.local/lib/python3.12/site-packages/airflow/models/taskinstance.py", line 734, in _execute_callable
    return ExecutionCallableRunner(
           ^^^^^^^^^^^^^^^^^^^^^^^^
  File "/home/airflow/.local/lib/python3.12/site-packages/airflow/utils/operator_helpers.py", line 252, in run
    return self.func(*args, **kwargs)
           ^^^^^^^^^^^^^^^^^^^^^^^^^^
  File "/home/airflow/.local/lib/python3.12/site-packages/cosmos/operators/base.py", line 299, in execute
    self.build_and_run_cmd(context=context, cmd_flags=self.add_cmd_flags())
  File "/home/airflow/.local/lib/python3.12/site-packages/cosmos/operators/local.py", line 708, in build_and_run_cmd
    result = self.run_command(
             ^^^^^^^^^^^^^^^^^
  File "/home/airflow/.local/lib/python3.12/site-packages/cosmos/operators/local.py", line 556, in run_command
    self.handle_exception(result)
  File "/home/airflow/.local/lib/python3.12/site-packages/cosmos/operators/local.py", line 227, in handle_exception_dbt_runner
    return dbt_runner.handle_exception_if_needed(result)
           ^^^^^^^^^^^^^^^^^^^^^^^^^^^^^^^^^^^^^^^^^^^^^
  File "/home/airflow/.local/lib/python3.12/site-packages/cosmos/dbt/runner.py", line 113, in handle_exception_if_needed
    raise CosmosDbtRunError(f"dbt invocation completed with errors: {error_message}")
cosmos.exceptions.CosmosDbtRunError: dbt invocation completed with errors: meta_ads_ads: Database Error in model meta_ads_ads (models/staging/meta_ads/meta_ads_ads.sql)
  column "adset_id" does not exist
  LINE 10:         adset_id,
                   ^
  compiled code at target/run/dbt_biera/models/staging/meta_ads/meta_ads_ads.sql
[2025-04-07T13:39:37.078+0000] {logging_mixin.py:190} INFO - Task instance in failure state
[2025-04-07T13:39:37.079+0000] {logging_mixin.py:190} INFO - Task start:2025-04-07 13:39:33.849412+00:00 end:2025-04-07 13:39:37.078361+00:00 duration:3.228949
[2025-04-07T13:39:37.079+0000] {logging_mixin.py:190} INFO - Task:<Task(DbtRunLocalOperator): dbt_processing.data_transformations.meta_ads_ads_run> dag:<DAG: meta_ads_elt_pipeline> dagrun:<DagRun meta_ads_elt_pipeline @ 2025-04-07 13:37:14.373919+00:00: manual__2025-04-07T13:37:14.373919+00:00, state:running, queued_at: 2025-04-07 13:37:14.393104+00:00. externally triggered: True>
[2025-04-07T13:39:37.079+0000] {logging_mixin.py:190} INFO - Failure caused by dbt invocation completed with errors: meta_ads_ads: Database Error in model meta_ads_ads (models/staging/meta_ads/meta_ads_ads.sql)
  column "adset_id" does not exist
  LINE 10:         adset_id,
                   ^
  compiled code at target/run/dbt_biera/models/staging/meta_ads/meta_ads_ads.sql
[2025-04-07T13:39:37.080+0000] {taskinstance.py:1226} INFO - Marking task as FAILED. dag_id=meta_ads_elt_pipeline, task_id=dbt_processing.data_transformations.meta_ads_ads_run, run_id=manual__2025-04-07T13:37:14.373919+00:00, execution_date=20250407T133714, start_date=20250407T133933, end_date=20250407T133937
[2025-04-07T13:39:37.112+0000] {taskinstance.py:341} INFO - ::group::Post task execution logs
[2025-04-07T13:39:37.113+0000] {standard_task_runner.py:124} ERROR - Failed to execute job 169 for task dbt_processing.data_transformations.meta_ads_ads_run (dbt invocation completed with errors: meta_ads_ads: Database Error in model meta_ads_ads (models/staging/meta_ads/meta_ads_ads.sql)
  column "adset_id" does not exist
  LINE 10:         adset_id,
                   ^
  compiled code at target/run/dbt_biera/models/staging/meta_ads/meta_ads_ads.sql; 9464)
Traceback (most recent call last):
  File "/home/airflow/.local/lib/python3.12/site-packages/airflow/task/task_runner/standard_task_runner.py", line 117, in _start_by_fork
    ret = args.func(args, dag=self.dag)
          ^^^^^^^^^^^^^^^^^^^^^^^^^^^^^
  File "/home/airflow/.local/lib/python3.12/site-packages/airflow/cli/cli_config.py", line 49, in command
    return func(*args, **kwargs)
           ^^^^^^^^^^^^^^^^^^^^^
  File "/home/airflow/.local/lib/python3.12/site-packages/airflow/utils/cli.py", line 116, in wrapper
    return f(*args, **kwargs)
           ^^^^^^^^^^^^^^^^^^
  File "/home/airflow/.local/lib/python3.12/site-packages/airflow/cli/commands/task_command.py", line 483, in task_run
    task_return_code = _run_task_by_selected_method(args, _dag, ti)
                       ^^^^^^^^^^^^^^^^^^^^^^^^^^^^^^^^^^^^^^^^^^^^
  File "/home/airflow/.local/lib/python3.12/site-packages/airflow/cli/commands/task_command.py", line 256, in _run_task_by_selected_method
    return _run_raw_task(args, ti)
           ^^^^^^^^^^^^^^^^^^^^^^^
  File "/home/airflow/.local/lib/python3.12/site-packages/airflow/cli/commands/task_command.py", line 341, in _run_raw_task
    return ti._run_raw_task(
           ^^^^^^^^^^^^^^^^^
  File "/home/airflow/.local/lib/python3.12/site-packages/airflow/utils/session.py", line 97, in wrapper
    return func(*args, session=session, **kwargs)
           ^^^^^^^^^^^^^^^^^^^^^^^^^^^^^^^^^^^^^^
  File "/home/airflow/.local/lib/python3.12/site-packages/airflow/models/taskinstance.py", line 3006, in _run_raw_task
    return _run_raw_task(
           ^^^^^^^^^^^^^^
  File "/home/airflow/.local/lib/python3.12/site-packages/airflow/models/taskinstance.py", line 274, in _run_raw_task
    TaskInstance._execute_task_with_callbacks(
  File "/home/airflow/.local/lib/python3.12/site-packages/airflow/models/taskinstance.py", line 3161, in _execute_task_with_callbacks
    result = self._execute_task(context, task_orig)
             ^^^^^^^^^^^^^^^^^^^^^^^^^^^^^^^^^^^^^^
  File "/home/airflow/.local/lib/python3.12/site-packages/airflow/models/taskinstance.py", line 3185, in _execute_task
    return _execute_task(self, context, task_orig)
           ^^^^^^^^^^^^^^^^^^^^^^^^^^^^^^^^^^^^^^^
  File "/home/airflow/.local/lib/python3.12/site-packages/airflow/models/taskinstance.py", line 768, in _execute_task
    result = _execute_callable(context=context, **execute_callable_kwargs)
             ^^^^^^^^^^^^^^^^^^^^^^^^^^^^^^^^^^^^^^^^^^^^^^^^^^^^^^^^^^^^^
  File "/home/airflow/.local/lib/python3.12/site-packages/airflow/models/taskinstance.py", line 734, in _execute_callable
    return ExecutionCallableRunner(
           ^^^^^^^^^^^^^^^^^^^^^^^^
  File "/home/airflow/.local/lib/python3.12/site-packages/airflow/utils/operator_helpers.py", line 252, in run
    return self.func(*args, **kwargs)
           ^^^^^^^^^^^^^^^^^^^^^^^^^^
  File "/home/airflow/.local/lib/python3.12/site-packages/cosmos/operators/base.py", line 299, in execute
    self.build_and_run_cmd(context=context, cmd_flags=self.add_cmd_flags())
  File "/home/airflow/.local/lib/python3.12/site-packages/cosmos/operators/local.py", line 708, in build_and_run_cmd
    result = self.run_command(
             ^^^^^^^^^^^^^^^^^
  File "/home/airflow/.local/lib/python3.12/site-packages/cosmos/operators/local.py", line 556, in run_command
    self.handle_exception(result)
  File "/home/airflow/.local/lib/python3.12/site-packages/cosmos/operators/local.py", line 227, in handle_exception_dbt_runner
    return dbt_runner.handle_exception_if_needed(result)
           ^^^^^^^^^^^^^^^^^^^^^^^^^^^^^^^^^^^^^^^^^^^^^
  File "/home/airflow/.local/lib/python3.12/site-packages/cosmos/dbt/runner.py", line 113, in handle_exception_if_needed
    raise CosmosDbtRunError(f"dbt invocation completed with errors: {error_message}")
cosmos.exceptions.CosmosDbtRunError: dbt invocation completed with errors: meta_ads_ads: Database Error in model meta_ads_ads (models/staging/meta_ads/meta_ads_ads.sql)
  column "adset_id" does not exist
  LINE 10:         adset_id,
                   ^
  compiled code at target/run/dbt_biera/models/staging/meta_ads/meta_ads_ads.sql
[2025-04-07T13:39:37.178+0000] {local_task_job_runner.py:266} INFO - Task exited with return code 1
[2025-04-07T13:39:37.200+0000] {taskinstance.py:3901} INFO - 0 downstream tasks scheduled from follow-on schedule check
[2025-04-07T13:39:37.203+0000] {local_task_job_runner.py:245} INFO - ::endgroup::
